Workbook
Name 切片器_是否属三无消费: #N/A
Name 切片器_姓名: #N/A
Name 切片器_账龄区间: #N/A
Name 切片器_账龄区间1: #N/A

Sheet 汇总-1月
A1: 结算系统酒店名称 | B1: 酒店简称 | C1: 收入 | H1: 经营毛利（行业口径） | M1: 业主利润返还（上报口径） | R1: 整体 | T1: 客房 | Y1: 餐饮 | AB1: 未分配
C2: 完成 | D2: 指标 | E2: 完成率 | F2: 同期 | G2: 同比率 | H2: 完成 | I2: 指标 | J2: 完成率 | K2: 同期 | L2: 同比率 | M2: 完成 | N2: 指标 | O2: 完成率 | P2: 同期 | Q2: 同比率 | R2: 元均创收（元） | S2: GOP率 | T2: OCC | U2: ADR（元） | V2: RevPAR（元） | W2: 元均创收（元） | X2: 客房利润率 | Y2: 毛利率 | Z2: 元均创收（元） | AA2: 餐饮利润率 | AB2: 能耗占比 | AC2: 元均创收（元） | AD2: 营销费用率 | AE2: 未分配费用占比
B3: 汇总 | C3: =SUM(C5:C7) -> 409.74156 | D3: =SUM(D5:D7) -> 448.34059 | E3: =C3/D3 -> 0.91390691 | F3: =SUM(F5:F7) -> 500.19513 | G3: =C3/F3-1 -> -0.18083656 | H3: =SUM(H5:H7) -> -64.698091 | I3: =SUM(I5:I7) -> -46.843093 | J3: =H3/I3 -> 1.3811661 | K3: =SUM(K5:K7) -> -71.212733 | L3: =IF(K3>0,H3/K3-1,IF(K3<0,1-H3/K3,"")) -> 0.091481421 | M3: =SUM(M5:M7) -> -102.33954 | N3: =SUM(N5:N7) -> -85.370055 | O3: =IF(N3<0,2-M3/N3,M3/N3) -> 0.80122434 | P3: =SUM(P5:P7) -> -116.62855 | Q3: =IF(P3>0,M3/P3-1,IF(P3<0,1-M3/P3,"")) -> 0.1225172 | R3: ='汇总明细-1月'!R3 -> 2.1563777 | S3: ='汇总明细-1月'!S3 -> -0.15789975 | T3: ='汇总明细-1月'!T3 -> 0.21552663 | W3: ='汇总明细-1月'!W3 -> 3.6946797 | X3: ='汇总明细-1月'!X3 -> 0.54364998 | Y3: ='汇总明细-1月'!Y3 -> 0.55209861 | Z3: ='汇总明细-1月'!Z3 -> 3.9033234 | AA3: ='汇总明细-1月'!AA3 -> 0.26807803 | AB3: ='汇总明细-1月'!AB3 -> 0.29535062 | AC3: ='汇总明细-1月'!AC3 -> 4.7004373 | AD3: ='汇总明细-1月'!AD3 -> 0.027139483 | AE3: ='汇总明细-1月'!AE3 -> 0.56572205
B4: 凤悦事业部合计： | C4: =SUM(C5:C7) -> 409.74156 | D4: =SUM(D5:D7) -> 448.34059 | E4: =C4/D4 -> 0.91390691 | F4: =SUM(F5:F7) -> 500.19513 | G4: =C4/F4-1 -> -0.18083656 | H4: =SUM(H5:H7) -> -64.698091 | I4: =SUM(I5:I7) -> -46.843093 | J4: =H4/I4 -> 1.3811661 | K4: =SUM(K5:K7) -> -71.212733 | L4: =IF(K4>0,H4/K4-1,IF(K4<0,1-H4/K4,"")) -> 0.091481421 | M4: =SUM(M5:M7) -> -102.33954 | N4: =SUM(N5:N7) -> -85.370055 | O4: =IF(N4<0,2-M4/N4,M4/N4) -> 0.80122434 | P4: =SUM(P5:P7) -> -116.62855 | Q4: =IF(P4>0,M4/P4-1,IF(P4<0,1-M4/P4,"")) -> 0.1225172 | R4: ='汇总明细-1月'!R4 -> 2.1563777 | S4: ='汇总明细-1月'!S4 -> -0.15789975 | T4: ='汇总明细-1月'!T4 -> 0.21552663 | W4: ='汇总明细-1月'!W4 -> 3.6946797 | X4: ='汇总明细-1月'!X4 -> 0.54364998 | Y4: ='汇总明细-1月'!Y4 -> 0.55209861 | Z4: ='汇总明细-1月'!Z4 -> 3.9033234 | AA4: ='汇总明细-1月'!AA4 -> 0.26807803 | AB4: ='汇总明细-1月'!AB4 -> 0.29535062 | AC4: ='汇总明细-1月'!AC4 -> 4.7004373 | AD4: ='汇总明细-1月'!AD4 -> 0.027139483 | AE4: ='汇总明细-1月'!AE4 -> 0.56572205
A5: 沈阳诺翰酒店 | B5: 于洪酒店 | C5: =VLOOKUP($B5,'汇总明细-1月'!$A$5:$AE$7,3,0)/10000 -> 283.18159 | D5: =VLOOKUP($B5,'汇总明细-1月'!$A$5:$AE$7,4,0)/10000 -> 269.12814 | E5: =VLOOKUP($B5,'汇总明细-1月'!$A$5:$AE$7,5,0) -> 1.0522184 | F5: =VLOOKUP($B5,'汇总明细-1月'!$A$5:$AE$7,6,0)/10000 -> 294.17345 | G5: =VLOOKUP($B5,'汇总明细-1月'!$A$5:$AE$7,7,0) -> -0.037365231 | H5: =VLOOKUP($B5,'汇总明细-1月'!$A$5:$AE$7,8,0)/10000 -> -34.304774 | I5: =VLOOKUP($B5,'汇总明细-1月'!$A$5:$AE$7,9,0)/10000 -> -25.19102 | J5: =VLOOKUP($B5,'汇总明细-1月'!$A$5:$AE$7,10,0) -> 0.63821417 | K5: =VLOOKUP($B5,'汇总明细-1月'!$A$5:$AE$7,11,0)/10000 -> -55.666638 | L5: =VLOOKUP($B5,'汇总明细-1月'!$A$5:$AE$7,12,0) -> 0.38374626 | M5: =VLOOKUP($B5,'汇总明细-1月'!$A$5:$AE$7,13,0)/10000 -> -58.735147 | N5: =VLOOKUP($B5,'汇总明细-1月'!$A$5:$AE$7,14,0)/10000 -> -51.220325 | O5: =VLOOKUP($B5,'汇总明细-1月'!$A$5:$AE$7,15,0) -> 0.85328437 | P5: =VLOOKUP($B5,'汇总明细-1月'!$A$5:$AE$7,16,0)/10000 -> -84.799468 | Q5: =VLOOKUP($B5,'汇总明细-1月'!$A$5:$AE$7,17,0) -> 0.3073642 | R5: =VLOOKUP($B5,'汇总明细-1月'!$A$5:$AE$7,18,0) -> 2.5475392 | S5: =VLOOKUP($B5,'汇总明细-1月'!$A$5:$AE$7,19,0) -> -0.12114055 | T5: =VLOOKUP($B5,'汇总明细-1月'!$A$5:$AE$7,20,0) -> 0.31282051 | U5: =VLOOKUP($B5,'汇总明细-1月'!$A$5:$AE$7,21,0) -> 199.24168 | V5: =VLOOKUP($B5,'汇总明细-1月'!$A$5:$AE$7,22,0) -> 62.326886 | W5: =VLOOKUP($B5,'汇总明细-1月'!$A$5:$AE$7,23,0) -> 3.9706353 | X5: =VLOOKUP($B5,'汇总明细-1月'!$A$5:$AE$7,24,0) -> 0.56916345 | Y5: =VLOOKUP($B5,'汇总明细-1月'!$A$5:$AE$7,25,0) -> 0.53898494 | Z5: =VLOOKUP($B5,'汇总明细-1月'!$A$5:$AE$7,26,0) -> 5.0071107 | AA5: =VLOOKUP($B5,'汇总明细-1月'!$A$5:$AE$7,27,0) -> 0.311165 | AB5: =VLOOKUP($B5,'汇总明细-1月'!$A$5:$AE$7,28,0) -> 0.33181395 | AC5: =VLOOKUP($B5,'汇总明细-1月'!$A$5:$AE$7,29,0) -> 5.5028084 | AD5: =VLOOKUP($B5,'汇总明细-1月'!$A$5:$AE$7,30,0) -> 0.02304718 | AE5: =VLOOKUP($B5,'汇总明细-1月'!$A$5:$AE$7,31,0) -> 0.55986208
A6: 碧桂园欧洲城凤凰酒店 | B6: 滁州酒店 | C6: =VLOOKUP($B6,'汇总明细-1月'!$A$5:$AE$7,3,0)/10000 -> 12.903087 | D6: =VLOOKUP($B6,'汇总明细-1月'!$A$5:$AE$7,4,0)/10000 -> 63.129571 | E6: =VLOOKUP($B6,'汇总明细-1月'!$A$5:$AE$7,5,0) -> 0.20439054 | F6: =VLOOKUP($B6,'汇总明细-1月'!$A$5:$AE$7,6,0)/10000 -> 80.842754 | G6: =VLOOKUP($B6,'汇总明细-1月'!$A$5:$AE$7,7,0) -> -0.84039278 | H6: =VLOOKUP($B6,'汇总明细-1月'!$A$5:$AE$7,8,0)/10000 -> -36.195544 | I6: =VLOOKUP($B6,'汇总明细-1月'!$A$5:$AE$7,9,0)/10000 -> -12.672792 | J6: =VLOOKUP($B6,'汇总明细-1月'!$A$5:$AE$7,10,0) -> -0.85616177 | K6: =VLOOKUP($B6,'汇总明细-1月'!$A$5:$AE$7,11,0)/10000 -> 2.398807 | L6: =VLOOKUP($B6,'汇总明细-1月'!$A$5:$AE$7,12,0) -> -16.088977 | M6: =VLOOKUP($B6,'汇总明细-1月'!$A$5:$AE$7,13,0)/10000 -> -40.646245 | N6: =VLOOKUP($B6,'汇总明细-1月'!$A$5:$AE$7,14,0)/10000 -> -17.685606 | O6: =VLOOKUP($B6,'汇总明细-1月'!$A$5:$AE$7,15,0) -> -0.29826702 | P6: =VLOOKUP($B6,'汇总明细-1月'!$A$5:$AE$7,16,0)/10000 -> -4.925041 | Q6: =VLOOKUP($B6,'汇总明细-1月'!$A$5:$AE$7,17,0) -> -7.252976 | R6: =VLOOKUP($B6,'汇总明细-1月'!$A$5:$AE$7,18,0) -> 0.51806265 | S6: =VLOOKUP($B6,'汇总明细-1月'!$A$5:$AE$7,19,0) -> -2.8051848 | T6: =VLOOKUP($B6,'汇总明细-1月'!$A$5:$AE$7,20,0) -> 0.032112758 | U6: =VLOOKUP($B6,'汇总明细-1月'!$A$5:$AE$7,21,0) -> 165.84338 | V6: =VLOOKUP($B6,'汇总明细-1月'!$A$5:$AE$7,22,0) -> 5.3256883 | W6: =VLOOKUP($B6,'汇总明细-1月'!$A$5:$AE$7,23,0) -> 0.81298809 | X6: =VLOOKUP($B6,'汇总明细-1月'!$A$5:$AE$7,24,0) -> -0.59771863 | Y6: =VLOOKUP($B6,'汇总明细-1月'!$A$5:$AE$7,25,0) -> 0.47804757 | Z6: =VLOOKUP($B6,'汇总明细-1月'!$A$5:$AE$7,26,0) -> 0.98638897 | AA6: =VLOOKUP($B6,'汇总明细-1月'!$A$5:$AE$7,27,0) -> -0.5975288 | AB6: =VLOOKUP($B6,'汇总明细-1月'!$A$5:$AE$7,28,0) -> 1.0659493 | AC6: =VLOOKUP($B6,'汇总明细-1月'!$A$5:$AE$7,29,0) -> 1.1984064 | AD6: =VLOOKUP($B6,'汇总明细-1月'!$A$5:$AE$7,30,0) -> 0.0016072898 | AE6: =VLOOKUP($B6,'汇总明细-1月'!$A$5:$AE$7,31,0) -> 2.2241329
A7: 武汉碧桂园凤凰酒店 | B7: 武汉酒店 | C7: =VLOOKUP($B7,'汇总明细-1月'!$A$5:$AE$7,3,0)/10000 -> 113.65688 | D7: =VLOOKUP($B7,'汇总明细-1月'!$A$5:$AE$7,4,0)/10000 -> 116.08287 | E7: =VLOOKUP($B7,'汇总明细-1月'!$A$5:$AE$7,5,0) -> 0.97910122 | F7: =VLOOKUP($B7,'汇总明细-1月'!$A$5:$AE$7,6,0)/10000 -> 125.17893 | G7: =VLOOKUP($B7,'汇总明细-1月'!$A$5:$AE$7,7,0) -> -0.092044583 | H7: =VLOOKUP($B7,'汇总明细-1月'!$A$5:$AE$7,8,0)/10000 -> 5.802227 | I7: =VLOOKUP($B7,'汇总明细-1月'!$A$5:$AE$7,9,0)/10000 -> -8.979281 | J7: =VLOOKUP($B7,'汇总明细-1月'!$A$5:$AE$7,10,0) -> 2.6461795 | K7: =VLOOKUP($B7,'汇总明细-1月'!$A$5:$AE$7,11,0)/10000 -> -17.944902 | L7: =VLOOKUP($B7,'汇总明细-1月'!$A$5:$AE$7,12,0) -> 1.3233357 | M7: =VLOOKUP($B7,'汇总明细-1月'!$A$5:$AE$7,13,0)/10000 -> -2.958152 | N7: =VLOOKUP($B7,'汇总明细-1月'!$A$5:$AE$7,14,0)/10000 -> -16.464124 | O7: =VLOOKUP($B7,'汇总明细-1月'!$A$5:$AE$7,15,0) -> 1.8203274 | P7: =VLOOKUP($B7,'汇总明细-1月'!$A$5:$AE$7,16,0)/10000 -> -26.904038 | Q7: =VLOOKUP($B7,'汇总明细-1月'!$A$5:$AE$7,17,0) -> 0.89004803 | R7: =VLOOKUP($B7,'汇总明细-1月'!$A$5:$AE$7,18,0) -> 2.1067655 | S7: =VLOOKUP($B7,'汇总明细-1月'!$A$5:$AE$7,19,0) -> 0.051050379 | T7: =VLOOKUP($B7,'汇总明细-1月'!$A$5:$AE$7,20,0) -> 0.22488062 | U7: =VLOOKUP($B7,'汇总明细-1月'!$A$5:$AE$7,21,0) -> 221.8789 | V7: =VLOOKUP($B7,'汇总明细-1月'!$A$5:$AE$7,22,0) -> 49.896264 | W7: =VLOOKUP($B7,'汇总明细-1月'!$A$5:$AE$7,23,0) -> 4.7829935 | X7: =VLOOKUP($B7,'汇总明细-1月'!$A$5:$AE$7,24,0) -> 0.60995125 | Y7: =VLOOKUP($B7,'汇总明细-1月'!$A$5:$AE$7,25,0) -> 0.59600743 | Z7: =VLOOKUP($B7,'汇总明细-1月'!$A$5:$AE$7,26,0) -> 3.2034786 | AA7: =VLOOKUP($B7,'汇总明细-1月'!$A$5:$AE$7,27,0) -> 0.26094614 | AB7: =VLOOKUP($B7,'汇总明细-1月'!$A$5:$AE$7,28,0) -> 0.117017 | AC7: =VLOOKUP($B7,'汇总明细-1月'!$A$5:$AE$7,29,0) -> 4.5567032 | AD7: =VLOOKUP($B7,'汇总明细-1月'!$A$5:$AE$7,30,0) -> 0.040234237 | AE7: =VLOOKUP($B7,'汇总明细-1月'!$A$5:$AE$7,31,0) -> 0.39204858

Sheet 汇总-累计
A1: 结算系统酒店名称 | B1: 酒店简称 | C1: 收入 | I1: 经营毛利（行业口径） | O1: 业主利润返还（上报口径） | U1: 整体 | W1: 客房 | AB1: 餐饮 | AE1: 未分配
C2: 完成 | D2: 指标 | E2: 完成率 | F2: 同期 | G2: 同比率 | H2: 全年完成率 | I2: 完成 | J2: 指标 | K2: 完成率 | L2: 同期 | M2: 同比率 | N2: 全年完成率 | O2: 完成 | P2: 指标 | Q2: 完成率 | R2: 同期 | S2: 同比率 | T2: 全年完成率 | U2: 元均创收（元） | V2: GOP率 | W2: OCC | X2: ADR（元） | Y2: RevPAR（元） | Z2: 元均创收（元） | AA2: 客房利润率 | AB2: 毛利率 | AC2: 元均创收（元） | AD2: 餐饮利润率 | AE2: 能耗占比 | AF2: 元均创收（元） | AG2: 营销费用率 | AH2: 未分配费用占比
B3: 汇总 | C3: =SUM(C5:C7) -> 409.74156 | D3: =SUM(D5:D7) -> 448.34059 | E3: =C3/D3 -> 0.91390691 | F3: =SUM(F5:F7) -> 500.19513 | G3: =C3/F3-1 -> -0.18083656 | H3: ='汇总明细-累计'!I3 -> 0.062357272 | I3: =SUM(I5:I7) -> -64.698091 | J3: =SUM(J5:J7) -> -46.843093 | K3: =I3/J3 -> 1.3811661 | L3: =SUM(L5:L7) -> -71.212733 | M3: =IF(L3>0,I3/L3-1,IF(L3<0,1-I3/L3,"")) -> 0.091481421 | N3: ='汇总明细-累计'!P3 -> -0.10734263 | O3: =SUM(O5:O7) -> -102.33954 | P3: =SUM(P5:P7) -> -85.370055 | Q3: =IF(P3<0,2-O3/P3,O3/P3) -> 0.80122434 | R3: =SUM(R5:R7) -> -116.62855 | S3: =IF(R3>0,O3/R3-1,IF(R3<0,1-O3/R3,"")) -> 0.1225172 | T3: ='汇总明细-累计'!W3 -> -0.76813958 | U3: ='汇总明细-累计'!X3 -> 2.1563777 | V3: ='汇总明细-累计'!Y3 -> -0.15789975 | W3: ='汇总明细-累计'!Z3 -> 0.21552663 | Z3: ='汇总明细-累计'!AC3 -> 3.6946797 | AA3: ='汇总明细-累计'!AD3 -> 0.54364998 | AB3: ='汇总明细-累计'!AE3 -> 0.55209861 | AC3: ='汇总明细-累计'!AF3 -> 3.9033234 | AD3: ='汇总明细-累计'!AG3 -> 0.26807803 | AE3: ='汇总明细-累计'!AH3 -> 0.29535062 | AF3: ='汇总明细-累计'!AI3 -> 4.7004373 | AG3: ='汇总明细-累计'!AJ3 -> 0.027139483 | AH3: ='汇总明细-累计'!AK3 -> 0.56572205
B4: 凤悦事业部合计： | C4: =SUM(C5:C7) -> 409.74156 | D4: =SUM(D5:D7) -> 448.34059 | E4: =C4/D4 -> 0.91390691 | F4: =SUM(F5:F7) -> 500.19513 | G4: =C4/F4-1 -> -0.18083656 | H4: ='汇总明细-累计'!I4 -> 0.062357272 | I4: =SUM(I5:I7) -> -64.698091 | J4: =SUM(J5:J7) -> -46.843093 | K4: =I4/J4 -> 1.3811661 | L4: =SUM(L5:L7) -> -71.212733 | M4: =IF(L4>0,I4/L4-1,IF(L4<0,1-I4/L4,"")) -> 0.091481421 | N4: ='汇总明细-累计'!P4 -> -0.10734263 | O4: =SUM(O5:O7) -> -102.33954 | P4: =SUM(P5:P7) -> -85.370055 | Q4: =IF(P4<0,2-O4/P4,O4/P4) -> 0.80122434 | R4: =SUM(R5:R7) -> -116.62855 | S4: =IF(R4>0,O4/R4-1,IF(R4<0,1-O4/R4,"")) -> 0.1225172 | T4: ='汇总明细-累计'!W4 -> -0.76813958 | U4: ='汇总明细-累计'!X4 -> 2.1563777 | V4: ='汇总明细-累计'!Y4 -> -0.15789975 | W4: ='汇总明细-累计'!Z4 -> 0.21552663 | Z4: ='汇总明细-累计'!AC4 -> 3.6946797 | AA4: ='汇总明细-累计'!AD4 -> 0.54364998 | AB4: ='汇总明细-累计'!AE4 -> 0.55209861 | AC4: ='汇总明细-累计'!AF4 -> 3.9033234 | AD4: ='汇总明细-累计'!AG4 -> 0.26807803 | AE4: ='汇总明细-累计'!AH4 -> 0.29535062 | AF4: ='汇总明细-累计'!AI4 -> 4.7004373 | AG4: ='汇总明细-累计'!AJ4 -> 0.027139483 | AH4: ='汇总明细-累计'!AK4 -> 0.56572205
A5: 沈阳诺翰酒店 | B5: 于洪酒店 | C5: =VLOOKUP($B5,'汇总明细-累计'!$A$5:$AK$23,3,0)/10000 -> 283.18159 | D5: =VLOOKUP($B5,'汇总明细-累计'!$A$5:$AK$23,4,0)/10000 -> 269.12814 | E5: =VLOOKUP($B5,'汇总明细-累计'!$A$5:$AK$23,5,0) -> 1.0522184 | F5: =VLOOKUP($B5,'汇总明细-累计'!$A$5:$AK$23,6,0)/10000 -> 294.17345 | G5: =VLOOKUP($B5,'汇总明细-累计'!$A$5:$AK$23,7,0) -> -0.037365231 | H5: =VLOOKUP($B5,'汇总明细-累计'!$A$5:$AK$23,9,0) -> 0.077214013 | I5: =VLOOKUP($B5,'汇总明细-累计'!$A$5:$AK$23,10,0)/10000 -> -34.304774 | J5: =VLOOKUP($B5,'汇总明细-累计'!$A$5:$AK$23,11,0)/10000 -> -25.19102 | K5: =VLOOKUP($B5,'汇总明细-累计'!$A$5:$AK$23,12,0) -> 0.63821417 | L5: =VLOOKUP($B5,'汇总明细-累计'!$A$5:$AK$23,13,0)/10000 -> -55.666638 | M5: =VLOOKUP($B5,'汇总明细-累计'!$A$5:$AK$23,14,0) -> 0.38374626 | N5: =VLOOKUP($B5,'汇总明细-累计'!$A$5:$AK$23,16,0) -> -0.10395386 | O5: =VLOOKUP($B5,'汇总明细-累计'!$A$5:$AK$23,17,0)/10000 -> -58.735147 | P5: =VLOOKUP($B5,'汇总明细-累计'!$A$5:$AK$23,18,0)/10000 -> -51.220325 | Q5: =VLOOKUP($B5,'汇总明细-累计'!$A$5:$AK$23,19,0) -> 0.85328437 | R5: =VLOOKUP($B5,'汇总明细-累计'!$A$5:$AK$23,20,0)/10000 -> -84.799468 | S5: =VLOOKUP($B5,'汇总明细-累计'!$A$5:$AK$23,21,0) -> 0.3073642 | T5: =VLOOKUP($B5,'汇总明细-累计'!$A$5:$AK$23,23,0) -> -2.39417 | U5: =VLOOKUP($B5,'汇总明细-累计'!$A$5:$AK$23,24,0) -> 2.5475392 | V5: =VLOOKUP($B5,'汇总明细-累计'!$A$5:$AK$23,25,0) -> -0.12114055 | W5: =VLOOKUP($B5,'汇总明细-累计'!$A$5:$AK$23,26,0) -> 0.31282051 | X5: =VLOOKUP($B5,'汇总明细-累计'!$A$5:$AK$23,27,0) -> 199.24168 | Y5: =VLOOKUP($B5,'汇总明细-累计'!$A$5:$AK$23,28,0) -> 62.326886 | Z5: =VLOOKUP($B5,'汇总明细-累计'!$A$5:$AK$23,29,0) -> 3.9706353 | AA5: =VLOOKUP($B5,'汇总明细-累计'!$A$5:$AK$23,30,0) -> 0.56916345 | AB5: =VLOOKUP($B5,'汇总明细-累计'!$A$5:$AK$23,31,0) -> 0.53898494 | AC5: =VLOOKUP($B5,'汇总明细-累计'!$A$5:$AK$23,32,0) -> 5.0071107 | AD5: =VLOOKUP($B5,'汇总明细-累计'!$A$5:$AK$23,33,0) -> 0.311165 | AE5: =VLOOKUP($B5,'汇总明细-累计'!$A$5:$AK$23,34,0) -> 0.33181395 | AF5: =VLOOKUP($B5,'汇总明细-累计'!$A$5:$AK$23,35,0) -> 5.5028084 | AG5: =VLOOKUP($B5,'汇总明细-累计'!$A$5:$AK$23,36,0) -> 0.02304718 | AH5: =VLOOKUP($B5,'汇总明细-累计'!$A$5:$AK$23,37,0) -> 0.55986208
A6: 碧桂园欧洲城凤凰酒店 | B6: 滁州酒店 | C6: =VLOOKUP($B6,'汇总明细-累计'!$A$5:$AK$23,3,0)/10000 -> 12.903087 | D6: =VLOOKUP($B6,'汇总明细-累计'!$A$5:$AK$23,4,0)/10000 -> 63.129571 | E6: =VLOOKUP($B6,'汇总明细-累计'!$A$5:$AK$23,5,0) -> 0.20439054 | F6: =VLOOKUP($B6,'汇总明细-累计'!$A$5:$AK$23,6,0)/10000 -> 80.842754 | G6: =VLOOKUP($B6,'汇总明细-累计'!$A$5:$AK$23,7,0) -> -0.84039278 | H6: =VLOOKUP($B6,'汇总明细-累计'!$A$5:$AK$23,9,0) -> 0.011502979 | I6: =VLOOKUP($B6,'汇总明细-累计'!$A$5:$AK$23,10,0)/10000 -> -36.195544 | J6: =VLOOKUP($B6,'汇总明细-累计'!$A$5:$AK$23,11,0)/10000 -> -12.672792 | K6: =VLOOKUP($B6,'汇总明细-累计'!$A$5:$AK$23,12,0) -> -0.85616177 | L6: =VLOOKUP($B6,'汇总明细-累计'!$A$5:$AK$23,13,0)/10000 -> 2.398807 | M6: =VLOOKUP($B6,'汇总明细-累计'!$A$5:$AK$23,14,0) -> -16.088977 | N6: =VLOOKUP($B6,'汇总明细-累计'!$A$5:$AK$23,16,0) -> -0.47625696 | O6: =VLOOKUP($B6,'汇总明细-累计'!$A$5:$AK$23,17,0)/10000 -> -40.646245 | P6: =VLOOKUP($B6,'汇总明细-累计'!$A$5:$AK$23,18,0)/10000 -> -17.685606 | Q6: =VLOOKUP($B6,'汇总明细-累计'!$A$5:$AK$23,19,0) -> -0.29826702 | R6: =VLOOKUP($B6,'汇总明细-累计'!$A$5:$AK$23,20,0)/10000 -> -4.925041 | S6: =VLOOKUP($B6,'汇总明细-累计'!$A$5:$AK$23,21,0) -> -7.252976 | T6: =VLOOKUP($B6,'汇总明细-累计'!$A$5:$AK$23,23,0) -> -3.9143876 | U6: =VLOOKUP($B6,'汇总明细-累计'!$A$5:$AK$23,24,0) -> 0.51806265 | V6: =VLOOKUP($B6,'汇总明细-累计'!$A$5:$AK$23,25,0) -> -2.8051848 | W6: =VLOOKUP($B6,'汇总明细-累计'!$A$5:$AK$23,26,0) -> 0.032112758 | X6: =VLOOKUP($B6,'汇总明细-累计'!$A$5:$AK$23,27,0) -> 165.84338 | Y6: =VLOOKUP($B6,'汇总明细-累计'!$A$5:$AK$23,28,0) -> 5.3256883 | Z6: =VLOOKUP($B6,'汇总明细-累计'!$A$5:$AK$23,29,0) -> 0.81298809 | AA6: =VLOOKUP($B6,'汇总明细-累计'!$A$5:$AK$23,30,0) -> -0.59771863 | AB6: =VLOOKUP($B6,'汇总明细-累计'!$A$5:$AK$23,31,0) -> 0.47804757 | AC6: =VLOOKUP($B6,'汇总明细-累计'!$A$5:$AK$23,32,0) -> 0.98638897 | AD6: =VLOOKUP($B6,'汇总明细-累计'!$A$5:$AK$23,33,0) -> -0.5975288 | AE6: =VLOOKUP($B6,'汇总明细-累计'!$A$5:$AK$23,34,0) -> 1.0659493 | AF6: =VLOOKUP($B6,'汇总明细-累计'!$A$5:$AK$23,35,0) -> 1.1984064 | AG6: =VLOOKUP($B6,'汇总明细-累计'!$A$5:$AK$23,36,0) -> 0.0016072898 | AH6: =VLOOKUP($B6,'汇总明细-累计'!$A$5:$AK$23,37,0) -> 2.2241329
A7: 武汉碧桂园凤凰酒店 | B7: 武汉酒店 | C7: =VLOOKUP($B7,'汇总明细-累计'!$A$5:$AK$23,3,0)/10000 -> 113.65688 | D7: =VLOOKUP($B7,'汇总明细-累计'!$A$5:$AK$23,4,0)/10000 -> 116.08287 | E7: =VLOOKUP($B7,'汇总明细-累计'!$A$5:$AK$23,5,0) -> 0.97910122 | F7: =VLOOKUP($B7,'汇总明细-累计'!$A$5:$AK$23,6,0)/10000 -> 125.17893 | G7: =VLOOKUP($B7,'汇总明细-累计'!$A$5:$AK$23,7,0) -> -0.092044583 | H7: =VLOOKUP($B7,'汇总明细-累计'!$A$5:$AK$23,9,0) -> 0.063792549 | I7: =VLOOKUP($B7,'汇总明细-累计'!$A$5:$AK$23,10,0)/10000 -> 5.802227 | J7: =VLOOKUP($B7,'汇总明细-累计'!$A$5:$AK$23,11,0)/10000 -> -8.979281 | K7: =VLOOKUP($B7,'汇总明细-累计'!$A$5:$AK$23,12,0) -> 2.6461795 | L7: =VLOOKUP($B7,'汇总明细-累计'!$A$5:$AK$23,13,0)/10000 -> -17.944902 | M7: =VLOOKUP($B7,'汇总明细-累计'!$A$5:$AK$23,14,0) -> 1.3233357 | N7: =VLOOKUP($B7,'汇总明细-累计'!$A$5:$AK$23,16,0) -> 0.029494095 | O7: =VLOOKUP($B7,'汇总明细-累计'!$A$5:$AK$23,17,0)/10000 -> -2.958152 | P7: =VLOOKUP($B7,'汇总明细-累计'!$A$5:$AK$23,18,0)/10000 -> -16.464124 | Q7: =VLOOKUP($B7,'汇总明细-累计'!$A$5:$AK$23,19,0) -> 1.8203274 | R7: =VLOOKUP($B7,'汇总明细-累计'!$A$5:$AK$23,20,0)/10000 -> -26.904038 | S7: =VLOOKUP($B7,'汇总明细-累计'!$A$5:$AK$23,21,0) -> 0.89004803 | T7: =VLOOKUP($B7,'汇总明细-累计'!$A$5:$AK$23,23,0) -> -0.030088811 | U7: =VLOOKUP($B7,'汇总明细-累计'!$A$5:$AK$23,24,0) -> 2.1067655 | V7: =VLOOKUP($B7,'汇总明细-累计'!$A$5:$AK$23,25,0) -> 0.051050379 | W7: =VLOOKUP($B7,'汇总明细-累计'!$A$5:$AK$23,26,0) -> 0.22488062 | X7: =VLOOKUP($B7,'汇总明细-累计'!$A$5:$AK$23,27,0) -> 221.8789 | Y7: =VLOOKUP($B7,'汇总明细-累计'!$A$5:$AK$23,28,0) -> 49.896264 | Z7: =VLOOKUP($B7,'汇总明细-累计'!$A$5:$AK$23,29,0) -> 4.7829935 | AA7: =VLOOKUP($B7,'汇总明细-累计'!$A$5:$AK$23,30,0) -> 0.60995125 | AB7: =VLOOKUP($B7,'汇总明细-累计'!$A$5:$AK$23,31,0) -> 0.59600743 | AC7: =VLOOKUP($B7,'汇总明细-累计'!$A$5:$AK$23,32,0) -> 3.2034786 | AD7: =VLOOKUP($B7,'汇总明细-累计'!$A$5:$AK$23,33,0) -> 0.26094614 | AE7: =VLOOKUP($B7,'汇总明细-累计'!$A$5:$AK$23,34,0) -> 0.117017 | AF7: =VLOOKUP($B7,'汇总明细-累计'!$A$5:$AK$23,35,0) -> 4.5567032 | AG7: =VLOOKUP($B7,'汇总明细-累计'!$A$5:$AK$23,36,0) -> 0.040234237 | AH7: =VLOOKUP($B7,'汇总明细-累计'!$A$5:$AK$23,37,0) -> 0.39204858

Sheet 资管部
G1: 2025年经营收入分类—万元 | H1: 2025年经营收入分类—万元 | I1: 2025年经营收入分类—万元 | J1: 2025年经营收入分类—万元 | K1: 2025年经营收入分类—万元 | L1: 2025年经营收入分类—万元 | M1: 2025年经营收入分类—万元 | N1: 2025年经营收入分类—万元 | O1: 2025年经营收入分类—万元 | P1: 核心成本项情况 | Q1: 核心成本项情况 | R1: 核心成本项情况 | S1: 核心成本项情况 | T1: 核心成本项情况 | U1: 核心成本项情况 | V1: 核心成本项情况 | W1: 核心成本项情况 | X1: 核心成本项情况 | Y1: 2025年经营成本（直接成本）—万元 | Z1: 2025年经营成本（直接成本）—万元 | AA1: 2025年经营成本（直接成本）—万元 | AB1: 2025年经营成本（直接成本）—万元 | AC1: 2025年经营成本（直接成本）—万元 | AD1: 2025年经营成本（直接成本）—万元 | AE1: 2025年经营成本（直接成本）—万元 | AF1: 2025年经营成本（直接成本）—万元 | AG1: 2025年经营成本（直接成本）—万元 | AH1: 2025年经营成本（直接成本）—万元 | AI1: 2025年经营成本（直接成本）—万元 | AJ1: 2025年经营成本（直接成本）—万元 | AK1: 2025年经营成本（直接成本）—万元 | AL1: 2025年经营成本（直接成本）—万元 | AM1: 2025年经营成本（直接成本）—万元 | AN1: 2025年经营成本（直接成本）—万元 | AP1: 2025年经营成本（未分配费）—万元 | AQ1: 2025年经营成本（未分配费）—万元 | AR1: 2025年经营成本（未分配费）—万元 | AS1: 2025年经营成本（未分配费）—万元 | AT1: 2025年经营成本（未分配费）—万元 | AU1: 2025年经营成本（未分配费）—万元 | AV1: 2025年经营成本（未分配费）—万元 | AW1: 2025年经营成本（未分配费）—万元 | AX1: 2025年经营成本（未分配费）—万元 | AY1: 2025年经营成本（未分配费）—万元 | AZ1: 2025年经营成本（未分配费）—万元 | BA1: 2025年经营成本（未分配费）—万元 | BB1: 2025年经营成本（未分配费）—万元 | BC1: 2025年经营成本（未分配费）—万元 | BD1: 2025年经营成本（未分配费）—万元 | BE1: 2025年经营成本（未分配费）—万元 | BF1: 2025年经营成本（未分配费）—万元 | BG1: 非经营支出 | BH1: 非经营支出 | BI1: 非经营支出 | BJ1: 非经营支出 | BK1: 非经营支出 | BL1: 非经营支出 | BM1: 非经营支出 | BN1: 非经营支出 | BO1: 非经营支出 | BP1: 非经营支出
G2: 客房 | H2: 餐饮 | I2: 餐饮 | J2: 餐饮 | K2: 其他经营收入 | L2: 其他经营收入 | M2: 其他经营收入 | N2: 营业外收入 | O2: 合计 | P2: 薪酬及相关 | Q2: 薪酬及相关 | R2: 能耗 | S2: 能耗 | T2: 洗涤费 | U2: 洗涤费 | V2: 洗涤费 | W2: 维修费 | X2: 维修费 | Y2: 客房 | Z2: 客房 | AA2: 客房 | AB2: 客房 | AC2: 客房 | AD2: 客房 | AE2: 餐饮 | AF2: 餐饮 | AG2: 餐饮 | AH2: 餐饮 | AI2: 餐饮 | AJ2: 餐饮 | AK2: 新零售 | AL2: 康乐 | AM2: 租赁收入 | AN2: 租赁收入 | AO2: 合计 | AP2: 行政费用 | AQ2: 行政费用 | AR2: 营销费用 | AS2: 营销费用 | AT2: 营销费用 | AU2: 物业运营及保养 | AV2: 物业运营及保养 | AW2: 物业运营及保养 | AX2: 能耗 | AY2: 能耗 | AZ2: 能耗 | BA2: 能耗 | BB2: 能耗 | BE2: 能源优化 | BG2: 业主相关费用 | BH2: 业主相关费用 | BI2: 租金费用 | BJ2: 租金费用 | BK2: FFE | BL2: FFE | BM2: 非经营税费 | BN2: 其他非经营支出 | BO2: 其他非经营支出
B3: 酒店简称 | C3: 酒店简称2 | D3: 酒店全称 | E3: 收入check | F3: 总收入 | G3: 客房 | H3: 餐饮 | I3: 会议 | J3: 零售 | K3: 租赁收入 | L3: 康乐温泉收入 | M3: 其他经营收入 | P3: 薪酬及相关总额 | Q3: 薪酬及相关占比收入 | R3: 能耗总额 | S3: 能耗及相关占比收入 | T3: 洗涤费总额 | U3: 是否外洗 | V3: 洗涤占比收入 | W3: 维修费用总额 | X3: 维修费用占比收入 | Y3: 平均渠道费用 | Z3: 销售成本 | AA3: 运营费用-薪酬及相关 | AB3: 运营费用-洗涤费用 | AC3: 运营费用-其他 | AD3: 客房费用-check | AE3: 平均渠道费用 | AF3: 销售成本 | AG3: 运营费用-薪酬及相关 | AH3: 运营费用-洗涤费用 | AI3: 运营费用-其他 | AJ3: 费用-check | AK3: 购入成本 | AL3: 运营费用 | AM3: 佣金 | AN3: 其他 | AP3: 薪酬及相关 | AQ3: 其他 | AR3: 薪酬及相关 | AS3: 营销及推广 | AT3: 其他 | AU3: 薪酬及相关 | AV3: 维修费用 | AW3: 其他 | AX3: 电 | AY3: 水 | AZ3: 燃气 | BA3: 暖气 | BB3: 合计 | BC3: % | BD3: 能耗check | BE3: 是否安装 光伏、储能 | BF3: 是否有计划 安装光伏、储能 | BG3: 业主费用总额 | BH3: 情况说明 （主要项目、金额和发生原因） | BI3: 租金费用总额 | BJ3: 情况说明 （租赁原因、租赁成本、原因） | BK3: FFE总额 | BL3: 情况说明 （1、年度投入说明；2、费用超额和差额使用的原因） | BM3: 房产税及其他税费 | BN3: 金额 | BO3: 特殊情况说明 （如有） | BP3: 非经营check
F4: =SUM(F5:F38) -> #REF! | G4: =SUM(G5:G38) -> #REF! | H4: =SUM(H5:H38) -> #REF! | I4: =SUM(I5:I38) -> #REF! | J4: =SUM(J5:J38) -> #REF! | K4: =SUM(K5:K38) -> #REF! | L4: =SUM(L5:L38) -> #REF! | M4: =SUM(M5:M38) -> #REF! | ... O4: =SUM(O5:O38) -> #REF! | P4: =SUM(P5:P36) -> #REF! | Q4: =P4/F4 -> #REF! | R4: =SUM(R5:R36) -> #REF! | S4: =R4/F4 -> #REF! | T4: =SUM(T5:T36) -> #REF! | V4: =T4/F4 -> #REF! | W4: =SUM(W5:W36) -> #REF! | X4: =W4/F4 -> #REF! | Y4: =SUM(Y5:Y36) -> #VALUE! | Z4: =SUM(Z5:Z36) -> #VALUE! | AA4: =SUM(AA5:AA36) -> #REF! | AB4: =SUM(AB5:AB36) -> #VALUE! | AC4: =SUM(AC5:AC36) -> #VALUE! | AD4: =SUM(AD5:AD36) -> #VALUE! | AE4: =SUM(AE5:AE36) -> 0 | AF4: =SUM(AF5:AF36) -> #REF! | ... BA4: =SUM(BA5:BA36) -> #VALUE! | BB4: =SUM(BB5:BB40) -> #VALUE! | BC4: =BB4/F4 -> #VALUE! | BD4: =SUM(BD5:BD36) -> #VALUE! | BG4: =SUM(BG5:BG39) -> #REF! | BI4: =SUM(BI5:BI36) -> #REF! | BK4: =SUM(BK5:BK36) -> #REF! | BM4: =SUM(BM5:BM36) -> #REF! | BN4: =SUM(BN5:BN36) -> #REF! | BP4: =SUM(BP5:BP36) -> #REF!
A5: 于洪酒店 | B5: 于洪 | C5: 于洪酒店 | D5: 沈阳于洪碧桂园凤凰酒店有限公司 | E5: =SUM(G5:M5)-F5 -> 0 | F5: {=INDIRECT($B5&"!M16")} -> 2831815.9 | G5: {=INDIRECT($B5&"!M43")} -> 1138840.1 | H5: {=INDIRECT($B5&"!M52")+INDIRECT($B5&"!M53")} -> 1292584 | I5: {=INDIRECT($B5&"!M55")} -> 257360.45 | J5: {=INDIRECT($B5&"!M54")} -> 3062.53 | K5: {=INDIRECT($B5&"!M75")} -> 69952.73 | L5: {=INDIRECT($B5&"!M69")+INDIRECT($B5&"!M70")} -> 0 | M5: {=INDIRECT($B5&"!M77")-INDIRECT($B5&"!M75")-INDIRECT($B5&"!M69")-INDIRECT($B5&"!M70")} -> 70016.02 | N5: {=INDIRECT($B5&"!M115")} -> 1293.29 | O5: =SUM(G5:N5) -> 2833109.2 | P5: {=INDIRECT($B5&"!M31")} -> 1111588.8 | Q5: =P5/F5 -> 0.39253567 | R5: {=INDIRECT($B5&"!M34")} -> 939636.01 | S5: =R5/F5 -> 0.33181395 | T5: {=INDIRECT($B5&"!M38")} -> 61100.13 | V5: =T5/F5 -> 0.021576307 | W5: {=INDIRECT($B5&"!M36")} -> 46717.47 | X5: =W5/F5 -> 0.016497354 | Y5: =SUMIFS([1]客房!D:D,[1]客房!B:B,D5,[1]客房!C:C,"Reservation Fees 预订成本") -> #VALUE! | Z5: =SUMIFS([1]客房!D:D,[1]客房!B:B,D5,[1]客房!C:C," Total Cost of Sales 总销售成本") -> #VALUE! | AA5: {=INDIRECT($B5&"!M44")+INDIRECT($B5&"!M45")} -> 286815.6 | AB5: =SUMIFS([1]客房!D:D,[1]客房!B:B,D5,[1]客房!C:C,"Laundry 洗涤费") -> #VALUE! | AC5: {=INDIRECT($B5&"!M46")-Y5-Z5-AB5} -> #VALUE! | AD5: {=INDIRECT($B5&"!M47")-SUM(Y5:AC5)} -> #VALUE! | AF5: {=INDIRECT($B5&"!M60")} -> 715959.62 | AG5: {=INDIRECT($B5&"!M61")+INDIRECT($B5&"!M62")} -> 310160.31 | AH5: =SUMIFS([1]餐饮!D:D,[1]餐饮!B:B,D5,[1]餐饮!C:C,"Laundry 洗涤费") -> #VALUE! | AI5: {=INDIRECT($B5&"!M63")-AH5} -> #VALUE! | AJ5: {=INDIRECT($B5&"!M64")-SUM(AE5:AI5)} -> #VALUE! | AK5: =SUMIFS([1]新零售!D:D,[1]新零售!B:B,D5,[1]新零售!C:C,"Total Cost of Sales 总销售成本") -> #VALUE! | AL5: =SUMIFS([1]康乐温泉!C:C,[1]康乐温泉!A:A,D5,[1]康乐温泉!B:B,"Total Cost of Sales 总销售成本")+SUMIFS([1]康乐温泉!C:C,[1]康乐温泉!A:A,D5,[1]康乐温泉!B:B,"Total Other Expenses 其他费用合计") -> #VALUE! | AP5: {=INDIRECT($B5&"!M91")+INDIRECT($B5&"!M92")} -> 230985.86 | AQ5: {=INDIRECT($B5&"!M93")+INDIRECT($B5&"!M94")+INDIRECT($B5&"!M95")+INDIRECT($B5&"!M96")} -> 36049.66 | AR5: {=INDIRECT($B5&"!M98")+INDIRECT($B5&"!M99")} -> 147121.97 | AT5: {=INDIRECT($B5&"!M100")} -> 22962.37 | AU5: {=INDIRECT($B5&"!M103")+INDIRECT($B5&"!M104")} -> 136505.02 | AV5: {=INDIRECT($B5&"!M36")} -> 46717.47 | AW5: {=INDIRECT($B5&"!M105")-AV5} -> 25447.99 | AX5: =SUMIFS([1]能源!C:C,[1]能源!A:A,D5,[1]能源!B:B,"Electricity 电费") -> #VALUE! | AY5: =SUMIFS([1]能源!C:C,[1]能源!A:A,D5,[1]能源!B:B,"Steam 蒸汽费")+SUMIFS([1]能源!C:C,[1]能源!A:A,D5,[1]能源!B:B,"Geothermal water 地热水")+SUMIFS([1]能源!C:C,[1]能源!A:A,D5,[1]能源!B:B,"Water 水费") -> #VALUE! | AZ5: =SUMIFS([1]能源!C:C,[1]能源!A:A,D5,[1]能源!B:B,"Gas 煤气费")+SUMIFS([1]能源!C:C,[1]能源!A:A,D5,[1]能源!B:B,"Oil 燃油费") -> #VALUE! | BA5: =SUMIFS([1]能源!C:C,[1]能源!A:A,D5,[1]能源!B:B,"Heating 暖气") -> #VALUE! | BB5: =SUM(AX5:BA5) -> #VALUE! | BC5: =BB5/F5 -> #VALUE! | BD5: {=INDIRECT($B5&"!M101")-SUM(AX5:BA5)} -> #VALUE! | BG5: {=INDIRECT($B5&"!M119")} -> 0 | BI5: {=INDIRECT($B5&"!M116")} -> 418282.09 | BK5: {=INDIRECT($B5&"!M123")} -> 103771.04 | BM5: {=INDIRECT($B5&"!M117")} -> 0 | BN5: {=INDIRECT($B5&"!M118")+INDIRECT($B5&"!M120")} -> 3.84 | BP5: {=-INDIRECT($B5&"!M114")+INDIRECT($B5&"!M115")-BG5-BI5-BM5-BN5} -> -3.2596148e-11
A6: 滁州酒店 | B6: 滁州 | C6: 滁州酒店 | D6: 滁州碧桂园凤凰酒店管理有限公司 | E6: =SUM(G6:M6)-F6 -> 0 | F6: {=INDIRECT($B6&"!M16")} -> 129030.87 | G6: {=INDIRECT($B6&"!M43")} -> 55218.59 | H6: {=INDIRECT($B6&"!M52")+INDIRECT($B6&"!M53")} -> 60025.47 | I6: {=INDIRECT($B6&"!M55")} -> 1226.42 | J6: {=INDIRECT($B6&"!M54")} -> 11223.01 | K6: {=INDIRECT($B6&"!M75")} -> 1070.34 | L6: {=INDIRECT($B6&"!M69")+INDIRECT($B6&"!M70")} -> 0 | M6: {=INDIRECT($B6&"!M77")-INDIRECT($B6&"!M75")-INDIRECT($B6&"!M69")-INDIRECT($B6&"!M70")} -> 267.04 | N6: {=INDIRECT($B6&"!M115")} -> 236.25 | O6: =SUM(G6:N6) -> 129267.12 | P6: {=INDIRECT($B6&"!M31")} -> 249064.22 | Q6: =P6/F6 -> 1.9302685 | R6: {=INDIRECT($B6&"!M34")} -> 137540.37 | S6: =R6/F6 -> 1.0659493 | T6: {=INDIRECT($B6&"!M38")} -> 5609.22 | V6: =T6/F6 -> 0.043471923 | W6: {=INDIRECT($B6&"!M36")} -> 16743.95 | X6: =W6/F6 -> 0.12976701 | Y6: =SUMIFS([1]客房!D:D,[1]客房!B:B,D6,[1]客房!C:C,"Reservation Fees 预订成本") -> #VALUE! | Z6: =SUMIFS([1]客房!D:D,[1]客房!B:B,D6,[1]客房!C:C," Total Cost of Sales 总销售成本") -> #VALUE! | AA6: {=INDIRECT($B6&"!M44")+INDIRECT($B6&"!M45")} -> 67920.54 | AB6: =SUMIFS([1]客房!D:D,[1]客房!B:B,D6,[1]客房!C:C,"Laundry 洗涤费") -> #VALUE! | AC6: {=INDIRECT($B6&"!M46")-Y6-Z6-AB6} -> #VALUE! | AD6: {=INDIRECT($B6&"!M47")-SUM(Y6:AC6)} -> #VALUE! | AF6: {=INDIRECT($B6&"!M60")} -> 37828.45 | AG6: {=INDIRECT($B6&"!M61")+INDIRECT($B6&"!M62")} -> 73474.97 | AH6: =SUMIFS([1]餐饮!D:D,[1]餐饮!B:B,D6,[1]餐饮!C:C,"Laundry 洗涤费") -> #VALUE! | AI6: {=INDIRECT($B6&"!M63")-AH6} -> #VALUE! | AJ6: {=INDIRECT($B6&"!M64")-SUM(AE6:AI6)} -> #VALUE! | AK6: =SUMIFS([1]新零售!D:D,[1]新零售!B:B,D6,[1]新零售!C:C,"Total Cost of Sales 总销售成本") -> #VALUE! | AL6: =SUMIFS([1]康乐温泉!C:C,[1]康乐温泉!A:A,D6,[1]康乐温泉!B:B,"Total Cost of Sales 总销售成本")+SUMIFS([1]康乐温泉!C:C,[1]康乐温泉!A:A,D6,[1]康乐温泉!B:B,"Total Other Expenses 其他费用合计") -> #VALUE! | AP6: {=INDIRECT($B6&"!M91")+INDIRECT($B6&"!M92")} -> 40424.31 | AQ6: {=INDIRECT($B6&"!M93")+INDIRECT($B6&"!M94")+INDIRECT($B6&"!M95")+INDIRECT($B6&"!M96")} -> 23036.61 | AR6: {=INDIRECT($B6&"!M98")+INDIRECT($B6&"!M99")} -> 28150.53 | AT6: {=INDIRECT($B6&"!M100")} -> 2906.95 | AU6: {=INDIRECT($B6&"!M103")+INDIRECT($B6&"!M104")} -> 39093.87 | AV6: {=INDIRECT($B6&"!M36")} -> 16743.95 | AW6: {=INDIRECT($B6&"!M105")-AV6} -> -914.79 | AX6: =SUMIFS([1]能源!C:C,[1]能源!A:A,D6,[1]能源!B:B,"Electricity 电费") -> #VALUE! | AY6: =SUMIFS([1]能源!C:C,[1]能源!A:A,D6,[1]能源!B:B,"Steam 蒸汽费")+SUMIFS([1]能源!C:C,[1]能源!A:A,D6,[1]能源!B:B,"Geothermal water 地热水")+SUMIFS([1]能源!C:C,[1]能源!A:A,D6,[1]能源!B:B,"Water 水费") -> #VALUE! | AZ6: =SUMIFS([1]能源!C:C,[1]能源!A:A,D6,[1]能源!B:B,"Gas 煤气费")+SUMIFS([1]能源!C:C,[1]能源!A:A,D6,[1]能源!B:B,"Oil 燃油费") -> #VALUE! | BA6: =SUMIFS([1]能源!C:C,[1]能源!A:A,D6,[1]能源!B:B,"Heating 暖气") -> #VALUE! | BB6: =SUM(AX6:BA6) -> #VALUE! | BC6: =BB6/F6 -> #VALUE! | BD6: {=INDIRECT($B6&"!M101")-SUM(AX6:BA6)} -> #VALUE! | BG6: {=INDIRECT($B6&"!M119")} -> 0 | BI6: {=INDIRECT($B6&"!M116")} -> 146702.15 | BK6: {=INDIRECT($B6&"!M123")} -> 0 | BM6: {=INDIRECT($B6&"!M117")} -> 0 | BN6: {=INDIRECT($B6&"!M118")+INDIRECT($B6&"!M120")} -> 0 | BP6: {=-INDIRECT($B6&"!M114")+INDIRECT($B6&"!M115")-BG6-BI6-BM6-BN6} -> 0
A7: 武汉酒店 | B7: 武汉 | C7: 武汉酒店 | D7: 武汉市碧桂园凤凰酒店有限公司 | E7: =SUM(G7:M7)-F7 -> 0 | F7: {=INDIRECT($B7&"!M16")} -> 1136568.8 | G7: {=INDIRECT($B7&"!M43")} -> 512343.26 | H7: {=INDIRECT($B7&"!M52")+INDIRECT($B7&"!M53")} -> 506449.08 | I7: {=INDIRECT($B7&"!M55")} -> 72357.85 | J7: {=INDIRECT($B7&"!M54")} -> 7236.3 | K7: {=INDIRECT($B7&"!M75")} -> 36757.13 | L7: {=INDIRECT($B7&"!M69")+INDIRECT($B7&"!M70")} -> 0 | M7: {=INDIRECT($B7&"!M77")-INDIRECT($B7&"!M75")-INDIRECT($B7&"!M69")-INDIRECT($B7&"!M70")} -> 1425.21 | N7: {=INDIRECT($B7&"!M115")} -> 201.07 | O7: =SUM(G7:N7) -> 1136769.9 | P7: {=INDIRECT($B7&"!M31")} -> 539485.22 | Q7: =P7/F7 -> 0.47466128 | R7: {=INDIRECT($B7&"!M34")} -> 132997.87 | S7: =R7/F7 -> 0.117017 | T7: {=INDIRECT($B7&"!M38")} -> 16269.54 | V7: =T7/F7 -> 0.01431461 | W7: {=INDIRECT($B7&"!M36")} -> 18239.38 | X7: =W7/F7 -> 0.016047757 | Y7: =SUMIFS([1]客房!D:D,[1]客房!B:B,D7,[1]客房!C:C,"Reservation Fees 预订成本") -> #VALUE! | Z7: =SUMIFS([1]客房!D:D,[1]客房!B:B,D7,[1]客房!C:C," Total Cost of Sales 总销售成本") -> #VALUE! | AA7: {=INDIRECT($B7&"!M44")+INDIRECT($B7&"!M45")} -> 107117.7 | AB7: =SUMIFS([1]客房!D:D,[1]客房!B:B,D7,[1]客房!C:C,"Laundry 洗涤费") -> #VALUE! | AC7: {=INDIRECT($B7&"!M46")-Y7-Z7-AB7} -> #VALUE! | AD7: {=INDIRECT($B7&"!M47")-SUM(Y7:AC7)} -> #VALUE! | AF7: {=INDIRECT($B7&"!M60")} -> 236757.11 | AG7: {=INDIRECT($B7&"!M61")+INDIRECT($B7&"!M62")} -> 182939.64 | AH7: =SUMIFS([1]餐饮!D:D,[1]餐饮!B:B,D7,[1]餐饮!C:C,"Laundry 洗涤费") -> #VALUE! | AI7: {=INDIRECT($B7&"!M63")-AH7} -> #VALUE! | AJ7: {=INDIRECT($B7&"!M64")-SUM(AE7:AI7)} -> #VALUE! | AK7: =SUMIFS([1]新零售!D:D,[1]新零售!B:B,D7,[1]新零售!C:C,"Total Cost of Sales 总销售成本") -> #VALUE! | AL7: =SUMIFS([1]康乐温泉!C:C,[1]康乐温泉!A:A,D7,[1]康乐温泉!B:B,"Total Cost of Sales 总销售成本")+SUMIFS([1]康乐温泉!C:C,[1]康乐温泉!A:A,D7,[1]康乐温泉!B:B,"Total Other Expenses 其他费用合计") -> #VALUE! | AP7: {=INDIRECT($B7&"!M91")+INDIRECT($B7&"!M92")} -> 103554.28 | AQ7: {=INDIRECT($B7&"!M93")+INDIRECT($B7&"!M94")+INDIRECT($B7&"!M95")+INDIRECT($B7&"!M96")} -> 25160.42 | AR7: {=INDIRECT($B7&"!M98")+INDIRECT($B7&"!M99")} -> 79186.35 | AT7: {=INDIRECT($B7&"!M100")} -> 15316.58 | AU7: {=INDIRECT($B7&"!M103")+INDIRECT($B7&"!M104")} -> 66687.25 | AV7: {=INDIRECT($B7&"!M36")} -> 18239.38 | AW7: {=INDIRECT($B7&"!M105")-AV7} -> 4448.07 | AX7: =SUMIFS([1]能源!C:C,[1]能源!A:A,D7,[1]能源!B:B,"Electricity 电费") -> #VALUE! | AY7: =SUMIFS([1]能源!C:C,[1]能源!A:A,D7,[1]能源!B:B,"Steam 蒸汽费")+SUMIFS([1]能源!C:C,[1]能源!A:A,D7,[1]能源!B:B,"Geothermal water 地热水")+SUMIFS([1]能源!C:C,[1]能源!A:A,D7,[1]能源!B:B,"Water 水费") -> #VALUE! | AZ7: =SUMIFS([1]能源!C:C,[1]能源!A:A,D7,[1]能源!B:B,"Gas 煤气费")+SUMIFS([1]能源!C:C,[1]能源!A:A,D7,[1]能源!B:B,"Oil 燃油费") -> #VALUE! | BA7: =SUMIFS([1]能源!C:C,[1]能源!A:A,D7,[1]能源!B:B,"Heating 暖气") -> #VALUE! | BB7: =SUM(AX7:BA7) -> #VALUE! | BC7: =BB7/F7 -> #VALUE! | BD7: {=INDIRECT($B7&"!M101")-SUM(AX7:BA7)} -> #VALUE! | BG7: {=INDIRECT($B7&"!M119")} -> 0 | BI7: {=INDIRECT($B7&"!M116")} -> 0 | BK7: {=INDIRECT($B7&"!M123")} -> 0 | BM7: {=INDIRECT($B7&"!M117")} -> 139147.03 | BN7: {=INDIRECT($B7&"!M118")+INDIRECT($B7&"!M120")} -> 0 | BP7: {=-INDIRECT($B7&"!M114")+INDIRECT($B7&"!M115")-BG7-BI7-BM7-BN7} -> 0
A8: 海南临高 | B8: 临高 | C8: 临高酒店 | D8: 临高金碧酒店管理有限公司 | E8: =SUM(G8:M8)-F8 -> #REF! | F8: {=INDIRECT($B8&"!M16")} -> #REF! | G8: {=INDIRECT($B8&"!M43")} -> #REF! | H8: {=INDIRECT($B8&"!M52")+INDIRECT($B8&"!M53")} -> #REF! | I8: {=INDIRECT($B8&"!M55")} -> #REF! | J8: {=INDIRECT($B8&"!M54")} -> #REF! | K8: {=INDIRECT($B8&"!M75")} -> #REF! | L8: {=INDIRECT($B8&"!M69")+INDIRECT($B8&"!M70")} -> #REF! | M8: {=INDIRECT($B8&"!M77")-INDIRECT($B8&"!M75")-INDIRECT($B8&"!M69")-INDIRECT($B8&"!M70")} -> #REF! | N8: {=INDIRECT($B8&"!M115")} -> #REF! | O8: =SUM(G8:N8) -> #REF! | P8: {=INDIRECT($B8&"!M31")} -> #REF! | Q8: =P8/F8 -> #REF! | R8: {=INDIRECT($B8&"!M34")} -> #REF! | S8: =R8/F8 -> #REF! | T8: {=INDIRECT($B8&"!M38")} -> #REF! | V8: =T8/F8 -> #REF! | W8: {=INDIRECT($B8&"!M36")} -> #REF! | X8: =W8/F8 -> #REF! | Y8: =SUMIFS([1]客房!D:D,[1]客房!B:B,D8,[1]客房!C:C,"Reservation Fees 预订成本")+SUMIFS([1]客房!D:D,[1]客房!B:B,"海南临高碧桂园房地产开发有限公司酒店分公司",[1]客房!C:C,"Reservation Fees 预订成本") -> #VALUE! | Z8: =SUMIFS([1]客房!D:D,[1]客房!B:B,D8,[1]客房!C:C," Total Cost of Sales 总销售成本")+SUMIFS([1]客房!D:D,[1]客房!B:B,"海南临高碧桂园房地产开发有限公司酒店分公司",[1]客房!C:C," Total Cost of Sales 总销售成本") -> #VALUE! | AA8: {=INDIRECT($B8&"!M44")+INDIRECT($B8&"!M45")} -> #REF! | AB8: =SUMIFS([1]客房!D:D,[1]客房!B:B,D8,[1]客房!C:C,"Laundry 洗涤费")+SUMIFS([1]客房!D:D,[1]客房!B:B,"海南临高碧桂园房地产开发有限公司酒店分公司",[1]客房!C:C,"Laundry 洗涤费") -> #VALUE! | AC8: {=INDIRECT($B8&"!M46")-Y8-Z8-AB8} -> #REF! | AD8: {=INDIRECT($B8&"!M47")-SUM(Y8:AC8)} -> #REF! | AF8: {=INDIRECT($B8&"!M60")} -> #REF! | AG8: {=INDIRECT($B8&"!M61")+INDIRECT($B8&"!M62")} -> #REF! | AH8: =SUMIFS([1]餐饮!D:D,[1]餐饮!B:B,D8,[1]餐饮!C:C,"Laundry 洗涤费")+SUMIFS([1]餐饮!D:D,[1]餐饮!B:B,"海南临高碧桂园房地产开发有限公司酒店分公司",[1]餐饮!C:C,"Laundry 洗涤费") -> #VALUE! | AI8: {=INDIRECT($B8&"!M63")-AH8} -> #REF! | AJ8: {=INDIRECT($B8&"!M64")-SUM(AE8:AI8)} -> #REF! | AK8: =SUMIFS([1]新零售!D:D,[1]新零售!B:B,D8,[1]新零售!C:C,"Total Cost of Sales 总销售成本")+SUMIFS([1]新零售!D:D,[1]新零售!B:B,"海南临高碧桂园房地产开发有限公司酒店分公司",[1]新零售!C:C,"Total Cost of Sales 总销售成本") -> #VALUE! | AL8: =SUMIFS([1]康乐温泉!C:C,[1]康乐温泉!A:A,D8,[1]康乐温泉!B:B,"Total Cost of Sales 总销售成本")+SUMIFS([1]康乐温泉!C:C,[1]康乐温泉!A:A,D8,[1]康乐温泉!B:B,"Total Other Expenses 其他费用合计")+SUMIFS([1]康乐温泉!C:C,[1]康乐温泉!A:A,"海南临高碧桂园房地产开发有限公司酒店分公司",[1]康乐温泉!B:B,"Total Cost of Sales 总销售成本")+SUMIFS([1]康乐温泉!C:C,[1]康乐温泉!A:A,"海南临高碧桂园房地产开发有限公司酒店分公司",[1]康乐温泉!B:B,"Total Other Expenses 其他费用合计") -> #VALUE! | AP8: {=INDIRECT($B8&"!M91")+INDIRECT($B8&"!M92")} -> #REF! | AQ8: {=INDIRECT($B8&"!M93")+INDIRECT($B8&"!M94")+INDIRECT($B8&"!M95")+INDIRECT($B8&"!M96")} -> #REF! | AR8: {=INDIRECT($B8&"!M98")+INDIRECT($B8&"!M99")} -> #REF! | AT8: {=INDIRECT($B8&"!M100")} -> #REF! | AU8: {=INDIRECT($B8&"!M103")+INDIRECT($B8&"!M104")} -> #REF! | AV8: {=INDIRECT($B8&"!M36")} -> #REF! | AW8: {=INDIRECT($B8&"!M105")-AV8} -> #REF! | AX8: =SUMIFS([1]能源!C:C,[1]能源!A:A,D8,[1]能源!B:B,"Electricity 电费")+SUMIFS([1]能源!C:C,[1]能源!A:A,"海南临高碧桂园房地产开发有限公司酒店分公司",[1]能源!B:B,"Electricity 电费") -> #VALUE! | AY8: =SUMIFS([1]能源!C:C,[1]能源!A:A,D8,[1]能源!B:B,"Steam 蒸汽费")+SUMIFS([1]能源!C:C,[1]能源!A:A,D8,[1]能源!B:B,"Geothermal water 地热水")+SUMIFS([1]能源!C:C,[1]能源!A:A,D8,[1]能源!B:B,"Water 水费")+SUMIFS([1]能源!C:C,[1]能源!A:A,"海南临高碧桂园房地产开发有限公司酒店分公司",[1]能源!B:B,"Steam 蒸汽费")+SUMIFS([1]能源!C:C,[1]能源!A:A,"海南临高碧桂园房地产开发有限公司酒店分公司",[1]能源!B:B,"Geothermal water 地热水")+SUMIFS([1]能源!C:C,[1]能源!A:A,"海南临高碧桂园房地产开发有限公司酒店分公司",[1]能源!B:B,"Water 水费") -> #VALUE! | AZ8: =SUMIFS([1]能源!C:C,[1]能源!A:A,D8,[1]能源!B:B,"Gas 煤气费")+SUMIFS([1]能源!C:C,[1]能源!A:A,D8,[1]能源!B:B,"Oil 燃油费")+SUMIFS([1]能源!C:C,[1]能源!A:A,"海南临高碧桂园房地产开发有限公司酒店分公司",[1]能源!B:B,"Gas 煤气费")+SUMIFS([1]能源!C:C,[1]能源!A:A,"海南临高碧桂园房地产开发有限公司酒店分公司",[1]能源!B:B,"Oil 燃油费") -> #VALUE! | BA8: =SUMIFS([1]能源!C:C,[1]能源!A:A,D8,[1]能源!B:B,"Heating 暖气")+SUMIFS([1]能源!C:C,[1]能源!A:A,"海南临高碧桂园房地产开发有限公司酒店分公司",[1]能源!B:B,"Heating 暖气") -> #VALUE! | BB8: =SUM(AX8:BA8) -> #VALUE! | BC8: =BB8/F8 -> #VALUE! | BD8: {=INDIRECT($B8&"!M101")-SUM(AX8:BA8)} -> #REF! | BG8: {=INDIRECT($B8&"!M119")} -> #REF! | BI8: {=INDIRECT($B8&"!M116")} -> #REF! | BK8: {=INDIRECT($B8&"!M123")} -> #REF! | BM8: {=INDIRECT($B8&"!M117")} -> #REF! | BN8: {=INDIRECT($B8&"!M118")+INDIRECT($B8&"!M120")} -> #REF! | BP8: {=-INDIRECT($B8&"!M114")+INDIRECT($B8&"!M115")-BG8-BI8-BM8-BN8} -> #REF!
A9: 三水酒店 | B9: 三水 | C9: 三水酒店 | D9: 佛山市芯林瑚酒店管理有限公司 | E9: =SUM(G9:M9)-F9 -> #REF! | F9: {=INDIRECT($B9&"!M16")} -> #REF! | G9: {=INDIRECT($B9&"!M43")} -> #REF! | H9: {=INDIRECT($B9&"!M52")+INDIRECT($B9&"!M53")} -> #REF! | I9: {=INDIRECT($B9&"!M55")} -> #REF! | J9: {=INDIRECT($B9&"!M54")} -> #REF! | K9: {=INDIRECT($B9&"!M75")} -> #REF! | L9: {=INDIRECT($B9&"!M69")+INDIRECT($B9&"!M70")} -> #REF! | M9: {=INDIRECT($B9&"!M77")-INDIRECT($B9&"!M75")-INDIRECT($B9&"!M69")-INDIRECT($B9&"!M70")} -> #REF! | N9: {=INDIRECT($B9&"!M115")} -> #REF! | O9: =SUM(G9:N9) -> #REF! | P9: {=INDIRECT($B9&"!M31")} -> #REF! | Q9: =P9/F9 -> #REF! | R9: {=INDIRECT($B9&"!M34")} -> #REF! | S9: =R9/F9 -> #REF! | T9: {=INDIRECT($B9&"!M38")} -> #REF! | V9: =T9/F9 -> #REF! | W9: {=INDIRECT($B9&"!M36")} -> #REF! | X9: =W9/F9 -> #REF! | Y9: =SUMIFS([1]客房!D:D,[1]客房!B:B,D9,[1]客房!C:C,"Reservation Fees 预订成本") -> #VALUE! | Z9: =SUMIFS([1]客房!D:D,[1]客房!B:B,D9,[1]客房!C:C," Total Cost of Sales 总销售成本") -> #VALUE! | AA9: {=INDIRECT($B9&"!M44")+INDIRECT($B9&"!M45")} -> #REF! | AB9: =SUMIFS([1]客房!D:D,[1]客房!B:B,D9,[1]客房!C:C,"Laundry 洗涤费") -> #VALUE! | AC9: {=INDIRECT($B9&"!M46")-Y9-Z9-AB9} -> #REF! | AD9: {=INDIRECT($B9&"!M47")-SUM(Y9:AC9)} -> #REF! | AF9: {=INDIRECT($B9&"!M60")} -> #REF! | AG9: {=INDIRECT($B9&"!M61")+INDIRECT($B9&"!M62")} -> #REF! | AH9: =SUMIFS([1]餐饮!D:D,[1]餐饮!B:B,D9,[1]餐饮!C:C,"Laundry 洗涤费") -> #VALUE! | AI9: {=INDIRECT($B9&"!M63")-AH9} -> #REF! | AJ9: {=INDIRECT($B9&"!M64")-SUM(AE9:AI9)} -> #REF! | AK9: =SUMIFS([1]新零售!D:D,[1]新零售!B:B,D9,[1]新零售!C:C,"Total Cost of Sales 总销售成本") -> #VALUE! | AL9: =SUMIFS([1]康乐温泉!C:C,[1]康乐温泉!A:A,D9,[1]康乐温泉!B:B,"Total Cost of Sales 总销售成本")+SUMIFS([1]康乐温泉!C:C,[1]康乐温泉!A:A,D9,[1]康乐温泉!B:B,"Total Other Expenses 其他费用合计") -> #VALUE! | AP9: {=INDIRECT($B9&"!M91")+INDIRECT($B9&"!M92")} -> #REF! | AQ9: {=INDIRECT($B9&"!M93")+INDIRECT($B9&"!M94")+INDIRECT($B9&"!M95")+INDIRECT($B9&"!M96")} -> #REF! | AR9: {=INDIRECT($B9&"!M98")+INDIRECT($B9&"!M99")} -> #REF! | AT9: {=INDIRECT($B9&"!M100")} -> #REF! | AU9: {=INDIRECT($B9&"!M103")+INDIRECT($B9&"!M104")} -> #REF! | AV9: {=INDIRECT($B9&"!M36")} -> #REF! | AW9: {=INDIRECT($B9&"!M105")-AV9} -> #REF! | AX9: =SUMIFS([1]能源!C:C,[1]能源!A:A,D9,[1]能源!B:B,"Electricity 电费") -> #VALUE! | AY9: =SUMIFS([1]能源!C:C,[1]能源!A:A,D9,[1]能源!B:B,"Steam 蒸汽费")+SUMIFS([1]能源!C:C,[1]能源!A:A,D9,[1]能源!B:B,"Geothermal water 地热水")+SUMIFS([1]能源!C:C,[1]能源!A:A,D9,[1]能源!B:B,"Water 水费") -> #VALUE! | AZ9: =SUMIFS([1]能源!C:C,[1]能源!A:A,D9,[1]能源!B:B,"Gas 煤气费")+SUMIFS([1]能源!C:C,[1]能源!A:A,D9,[1]能源!B:B,"Oil 燃油费") -> #VALUE! | BA9: =SUMIFS([1]能源!C:C,[1]能源!A:A,D9,[1]能源!B:B,"Heating 暖气") -> #VALUE! | BB9: =SUM(AX9:BA9) -> #VALUE! | BC9: =BB9/F9 -> #VALUE! | BD9: {=INDIRECT($B9&"!M101")-SUM(AX9:BA9)} -> #REF! | BG9: {=INDIRECT($B9&"!M119")} -> #REF! | BI9: {=INDIRECT($B9&"!M116")} -> #REF! | BK9: {=INDIRECT($B9&"!M123")} -> #REF! | BM9: {=INDIRECT($B9&"!M117")} -> #REF! | BN9: {=INDIRECT($B9&"!M118")+INDIRECT($B9&"!M120")} -> #REF! | BP9: {=-INDIRECT($B9&"!M114")+INDIRECT($B9&"!M115")-BG9-BI9-BM9-BN9} -> #REF!
A10: 泰州酒店 | B10: 泰州 | C10: 泰州酒店 | D10: 泰州市碧桂园凤凰酒店有限公司 | E10: =SUM(G10:M10)-F10 -> #REF! | F10: {=INDIRECT($B10&"!M16")} -> #REF! | G10: {=INDIRECT($B10&"!M43")} -> #REF! | H10: {=INDIRECT($B10&"!M52")+INDIRECT($B10&"!M53")} -> #REF! | I10: {=INDIRECT($B10&"!M55")} -> #REF! | J10: {=INDIRECT($B10&"!M54")} -> #REF! | K10: {=INDIRECT($B10&"!M75")} -> #REF! | L10: {=INDIRECT($B10&"!M69")+INDIRECT($B10&"!M70")} -> #REF! | M10: {=INDIRECT($B10&"!M77")-INDIRECT($B10&"!M75")-INDIRECT($B10&"!M69")-INDIRECT($B10&"!M70")} -> #REF! | N10: {=INDIRECT($B10&"!M115")} -> #REF! | O10: =SUM(G10:N10) -> #REF! | P10: {=INDIRECT($B10&"!M31")} -> #REF! | Q10: =P10/F10 -> #REF! | R10: {=INDIRECT($B10&"!M34")} -> #REF! | S10: =R10/F10 -> #REF! | T10: {=INDIRECT($B10&"!M38")} -> #REF! | V10: =T10/F10 -> #REF! | W10: {=INDIRECT($B10&"!M36")} -> #REF! | X10: =W10/F10 -> #REF! | Y10: =SUMIFS([1]客房!D:D,[1]客房!B:B,D10,[1]客房!C:C,"Reservation Fees 预订成本") -> #VALUE! | Z10: =SUMIFS([1]客房!D:D,[1]客房!B:B,D10,[1]客房!C:C," Total Cost of Sales 总销售成本") -> #VALUE! | AA10: {=INDIRECT($B10&"!M44")+INDIRECT($B10&"!M45")} -> #REF! | AB10: =SUMIFS([1]客房!D:D,[1]客房!B:B,D10,[1]客房!C:C,"Laundry 洗涤费") -> #VALUE! | AC10: {=INDIRECT($B10&"!M46")-Y10-Z10-AB10} -> #REF! | AD10: {=INDIRECT($B10&"!M47")-SUM(Y10:AC10)} -> #REF! | AF10: {=INDIRECT($B10&"!M60")} -> #REF! | AG10: {=INDIRECT($B10&"!M61")+INDIRECT($B10&"!M62")} -> #REF! | AH10: =SUMIFS([1]餐饮!D:D,[1]餐饮!B:B,D10,[1]餐饮!C:C,"Laundry 洗涤费") -> #VALUE! | AI10: {=INDIRECT($B10&"!M63")-AH10} -> #REF! | AJ10: {=INDIRECT($B10&"!M64")-SUM(AE10:AI10)} -> #REF! | AK10: =SUMIFS([1]新零售!D:D,[1]新零售!B:B,D10,[1]新零售!C:C,"Total Cost of Sales 总销售成本") -> #VALUE! | AL10: =SUMIFS([1]康乐温泉!C:C,[1]康乐温泉!A:A,D10,[1]康乐温泉!B:B,"Total Cost of Sales 总销售成本")+SUMIFS([1]康乐温泉!C:C,[1]康乐温泉!A:A,D10,[1]康乐温泉!B:B,"Total Other Expenses 其他费用合计") -> #VALUE! | AP10: {=INDIRECT($B10&"!M91")+INDIRECT($B10&"!M92")} -> #REF! | AQ10: {=INDIRECT($B10&"!M93")+INDIRECT($B10&"!M94")+INDIRECT($B10&"!M95")+INDIRECT($B10&"!M96")} -> #REF! | AR10: {=INDIRECT($B10&"!M98")+INDIRECT($B10&"!M99")} -> #REF! | AT10: {=INDIRECT($B10&"!M100")} -> #REF! | AU10: {=INDIRECT($B10&"!M103")+INDIRECT($B10&"!M104")} -> #REF! | AV10: {=INDIRECT($B10&"!M36")} -> #REF! | AW10: {=INDIRECT($B10&"!M105")-AV10} -> #REF! | AX10: =SUMIFS([1]能源!C:C,[1]能源!A:A,D10,[1]能源!B:B,"Electricity 电费") -> #VALUE! | AY10: =SUMIFS([1]能源!C:C,[1]能源!A:A,D10,[1]能源!B:B,"Steam 蒸汽费")+SUMIFS([1]能源!C:C,[1]能源!A:A,D10,[1]能源!B:B,"Geothermal water 地热水")+SUMIFS([1]能源!C:C,[1]能源!A:A,D10,[1]能源!B:B,"Water 水费") -> #VALUE! | AZ10: =SUMIFS([1]能源!C:C,[1]能源!A:A,D10,[1]能源!B:B,"Gas 煤气费")+SUMIFS([1]能源!C:C,[1]能源!A:A,D10,[1]能源!B:B,"Oil 燃油费") -> #VALUE! | BA10: =SUMIFS([1]能源!C:C,[1]能源!A:A,D10,[1]能源!B:B,"Heating 暖气") -> #VALUE! | BB10: =SUM(AX10:BA10) -> #VALUE! | BC10: =BB10/F10 -> #VALUE! | BD10: {=INDIRECT($B10&"!M101")-SUM(AX10:BA10)} -> #REF! | BG10: {=INDIRECT($B10&"!M119")} -> #REF! | BI10: {=INDIRECT($B10&"!M116")} -> #REF! | BK10: {=INDIRECT($B10&"!M123")} -> #REF! | BM10: {=INDIRECT($B10&"!M117")} -> #REF! | BN10: {=INDIRECT($B10&"!M118")+INDIRECT($B10&"!M120")} -> #REF! | BP10: {=-INDIRECT($B10&"!M114")+INDIRECT($B10&"!M115")-BG10-BI10-BM10-BN10} -> #REF!
A11: 安庆酒店 | B11: 安庆 | C11: 安庆酒店 | D11: 安庆碧桂园凤凰酒店有限公司 | E11: =SUM(G11:M11)-F11 -> #REF! | F11: {=INDIRECT($B11&"!M16")} -> #REF! | G11: {=INDIRECT($B11&"!M43")} -> #REF! | H11: {=INDIRECT($B11&"!M52")+INDIRECT($B11&"!M53")} -> #REF! | I11: {=INDIRECT($B11&"!M55")} -> #REF! | J11: {=INDIRECT($B11&"!M54")} -> #REF! | K11: {=INDIRECT($B11&"!M75")} -> #REF! | L11: {=INDIRECT($B11&"!M69")+INDIRECT($B11&"!M70")} -> #REF! | M11: {=INDIRECT($B11&"!M77")-INDIRECT($B11&"!M75")-INDIRECT($B11&"!M69")-INDIRECT($B11&"!M70")} -> #REF! | N11: {=INDIRECT($B11&"!M115")} -> #REF! | O11: =SUM(G11:N11) -> #REF! | P11: {=INDIRECT($B11&"!M31")} -> #REF! | Q11: =P11/F11 -> #REF! | R11: {=INDIRECT($B11&"!M34")} -> #REF! | S11: =R11/F11 -> #REF! | T11: {=INDIRECT($B11&"!M38")} -> #REF! | V11: =T11/F11 -> #REF! | W11: {=INDIRECT($B11&"!M36")} -> #REF! | X11: =W11/F11 -> #REF! | Y11: =SUMIFS([1]客房!D:D,[1]客房!B:B,D11,[1]客房!C:C,"Reservation Fees 预订成本") -> #VALUE! | Z11: =SUMIFS([1]客房!D:D,[1]客房!B:B,D11,[1]客房!C:C," Total Cost of Sales 总销售成本") -> #VALUE! | AA11: {=INDIRECT($B11&"!M44")+INDIRECT($B11&"!M45")} -> #REF! | AB11: =SUMIFS([1]客房!D:D,[1]客房!B:B,D11,[1]客房!C:C,"Laundry 洗涤费") -> #VALUE! | AC11: {=INDIRECT($B11&"!M46")-Y11-Z11-AB11} -> #REF! | AD11: {=INDIRECT($B11&"!M47")-SUM(Y11:AC11)} -> #REF! | AF11: {=INDIRECT($B11&"!M60")} -> #REF! | AG11: {=INDIRECT($B11&"!M61")+INDIRECT($B11&"!M62")} -> #REF! | AH11: =SUMIFS([1]餐饮!D:D,[1]餐饮!B:B,D11,[1]餐饮!C:C,"Laundry 洗涤费") -> #VALUE! | AI11: {=INDIRECT($B11&"!M63")-AH11} -> #REF! | AJ11: {=INDIRECT($B11&"!M64")-SUM(AE11:AI11)} -> #REF! | AK11: =SUMIFS([1]新零售!D:D,[1]新零售!B:B,D11,[1]新零售!C:C,"Total Cost of Sales 总销售成本") -> #VALUE! | AL11: =SUMIFS([1]康乐温泉!C:C,[1]康乐温泉!A:A,D11,[1]康乐温泉!B:B,"Total Cost of Sales 总销售成本")+SUMIFS([1]康乐温泉!C:C,[1]康乐温泉!A:A,D11,[1]康乐温泉!B:B,"Total Other Expenses 其他费用合计") -> #VALUE! | AP11: {=INDIRECT($B11&"!M91")+INDIRECT($B11&"!M92")} -> #REF! | AQ11: {=INDIRECT($B11&"!M93")+INDIRECT($B11&"!M94")+INDIRECT($B11&"!M95")+INDIRECT($B11&"!M96")} -> #REF! | AR11: {=INDIRECT($B11&"!M98")+INDIRECT($B11&"!M99")} -> #REF! | AT11: {=INDIRECT($B11&"!M100")} -> #REF! | AU11: {=INDIRECT($B11&"!M103")+INDIRECT($B11&"!M104")} -> #REF! | AV11: {=INDIRECT($B11&"!M36")} -> #REF! | AW11: {=INDIRECT($B11&"!M105")-AV11} -> #REF! | AX11: =SUMIFS([1]能源!C:C,[1]能源!A:A,D11,[1]能源!B:B,"Electricity 电费") -> #VALUE! | AY11: =SUMIFS([1]能源!C:C,[1]能源!A:A,D11,[1]能源!B:B,"Steam 蒸汽费")+SUMIFS([1]能源!C:C,[1]能源!A:A,D11,[1]能源!B:B,"Geothermal water 地热水")+SUMIFS([1]能源!C:C,[1]能源!A:A,D11,[1]能源!B:B,"Water 水费") -> #VALUE! | AZ11: =SUMIFS([1]能源!C:C,[1]能源!A:A,D11,[1]能源!B:B,"Gas 煤气费")+SUMIFS([1]能源!C:C,[1]能源!A:A,D11,[1]能源!B:B,"Oil 燃油费") -> #VALUE! | BA11: =SUMIFS([1]能源!C:C,[1]能源!A:A,D11,[1]能源!B:B,"Heating 暖气") -> #VALUE! | BB11: =SUM(AX11:BA11) -> #VALUE! | BC11: =BB11/F11 -> #VALUE! | BD11: {=INDIRECT($B11&"!M101")-SUM(AX11:BA11)} -> #REF! | BG11: {=INDIRECT($B11&"!M119")} -> #REF! | BI11: {=INDIRECT($B11&"!M116")} -> #REF! | BK11: {=INDIRECT($B11&"!M123")} -> #REF! | BM11: {=INDIRECT($B11&"!M117")} -> #REF! | BN11: {=INDIRECT($B11&"!M118")+INDIRECT($B11&"!M120")} -> #REF! | BP11: {=-INDIRECT($B11&"!M114")+INDIRECT($B11&"!M115")-BG11-BI11-BM11-BN11} -> #REF!
A12: 张家界酒店 | B12: 张家界 | C12: 张家界酒店 | D12: 张家界碧桂园凤凰酒店管理有限公司 | E12: =SUM(G12:M12)-F12 -> #REF! | F12: {=INDIRECT($B12&"!M16")} -> #REF! | G12: {=INDIRECT($B12&"!M43")} -> #REF! | H12: {=INDIRECT($B12&"!M52")+INDIRECT($B12&"!M53")} -> #REF! | I12: {=INDIRECT($B12&"!M55")} -> #REF! | J12: {=INDIRECT($B12&"!M54")} -> #REF! | K12: {=INDIRECT($B12&"!M75")} -> #REF! | L12: {=INDIRECT($B12&"!M69")+INDIRECT($B12&"!M70")} -> #REF! | M12: {=INDIRECT($B12&"!M77")-INDIRECT($B12&"!M75")-INDIRECT($B12&"!M69")-INDIRECT($B12&"!M70")} -> #REF! | N12: {=INDIRECT($B12&"!M115")} -> #REF! | O12: =SUM(G12:N12) -> #REF! | P12: {=INDIRECT($B12&"!M31")} -> #REF! | Q12: =P12/F12 -> #REF! | R12: {=INDIRECT($B12&"!M34")} -> #REF! | S12: =R12/F12 -> #REF! | T12: {=INDIRECT($B12&"!M38")} -> #REF! | V12: =T12/F12 -> #REF! | W12: {=INDIRECT($B12&"!M36")} -> #REF! | X12: =W12/F12 -> #REF! | Y12: =SUMIFS([1]客房!D:D,[1]客房!B:B,D12,[1]客房!C:C,"Reservation Fees 预订成本") -> #VALUE! | Z12: =SUMIFS([1]客房!D:D,[1]客房!B:B,D12,[1]客房!C:C," Total Cost of Sales 总销售成本") -> #VALUE! | AA12: {=INDIRECT($B12&"!M44")+INDIRECT($B12&"!M45")} -> #REF! | AB12: =SUMIFS([1]客房!D:D,[1]客房!B:B,D12,[1]客房!C:C,"Laundry 洗涤费") -> #VALUE! | AC12: {=INDIRECT($B12&"!M46")-Y12-Z12-AB12} -> #REF! | AD12: {=INDIRECT($B12&"!M47")-SUM(Y12:AC12)} -> #REF! | AF12: {=INDIRECT($B12&"!M60")} -> #REF! | AG12: {=INDIRECT($B12&"!M61")+INDIRECT($B12&"!M62")} -> #REF! | AH12: =SUMIFS([1]餐饮!D:D,[1]餐饮!B:B,D12,[1]餐饮!C:C,"Laundry 洗涤费") -> #VALUE! | AI12: {=INDIRECT($B12&"!M63")-AH12} -> #REF! | AJ12: {=INDIRECT($B12&"!M64")-SUM(AE12:AI12)} -> #REF! | AK12: =SUMIFS([1]新零售!D:D,[1]新零售!B:B,D12,[1]新零售!C:C,"Total Cost of Sales 总销售成本") -> #VALUE! | AL12: =SUMIFS([1]康乐温泉!C:C,[1]康乐温泉!A:A,D12,[1]康乐温泉!B:B,"Total Cost of Sales 总销售成本")+SUMIFS([1]康乐温泉!C:C,[1]康乐温泉!A:A,D12,[1]康乐温泉!B:B,"Total Other Expenses 其他费用合计") -> #VALUE! | AP12: {=INDIRECT($B12&"!M91")+INDIRECT($B12&"!M92")} -> #REF! | AQ12: {=INDIRECT($B12&"!M93")+INDIRECT($B12&"!M94")+INDIRECT($B12&"!M95")+INDIRECT($B12&"!M96")} -> #REF! | AR12: {=INDIRECT($B12&"!M98")+INDIRECT($B12&"!M99")} -> #REF! | AT12: {=INDIRECT($B12&"!M100")} -> #REF! | AU12: {=INDIRECT($B12&"!M103")+INDIRECT($B12&"!M104")} -> #REF! | AV12: {=INDIRECT($B12&"!M36")} -> #REF! | AW12: {=INDIRECT($B12&"!M105")-AV12} -> #REF! | AX12: =SUMIFS([1]能源!C:C,[1]能源!A:A,D12,[1]能源!B:B,"Electricity 电费") -> #VALUE! | AY12: =SUMIFS([1]能源!C:C,[1]能源!A:A,D12,[1]能源!B:B,"Steam 蒸汽费")+SUMIFS([1]能源!C:C,[1]能源!A:A,D12,[1]能源!B:B,"Geothermal water 地热水")+SUMIFS([1]能源!C:C,[1]能源!A:A,D12,[1]能源!B:B,"Water 水费") -> #VALUE! | AZ12: =SUMIFS([1]能源!C:C,[1]能源!A:A,D12,[1]能源!B:B,"Gas 煤气费")+SUMIFS([1]能源!C:C,[1]能源!A:A,D12,[1]能源!B:B,"Oil 燃油费") -> #VALUE! | BA12: =SUMIFS([1]能源!C:C,[1]能源!A:A,D12,[1]能源!B:B,"Heating 暖气") -> #VALUE! | BB12: =SUM(AX12:BA12) -> #VALUE! | BC12: =BB12/F12 -> #VALUE! | BD12: {=INDIRECT($B12&"!M101")-SUM(AX12:BA12)} -> #REF! | BG12: {=INDIRECT($B12&"!M119")} -> #REF! | BI12: {=INDIRECT($B12&"!M116")} -> #REF! | BK12: {=INDIRECT($B12&"!M123")} -> #REF! | BM12: {=INDIRECT($B12&"!M117")} -> #REF! | BN12: {=INDIRECT($B12&"!M118")+INDIRECT($B12&"!M120")} -> #REF! | BP12: {=-INDIRECT($B12&"!M114")+INDIRECT($B12&"!M115")-BG12-BI12-BM12-BN12} -> #REF!
A13: 句容酒店 | B13: 句容 | C13: 句容酒店 | D13: 句容碧桂园凤凰城酒店管理有限公司 | E13: =SUM(G13:M13)-F13 -> #REF! | F13: {=INDIRECT($B13&"!M16")} -> #REF! | G13: {=INDIRECT($B13&"!M43")} -> #REF! | H13: {=INDIRECT($B13&"!M52")+INDIRECT($B13&"!M53")} -> #REF! | I13: {=INDIRECT($B13&"!M55")} -> #REF! | J13: {=INDIRECT($B13&"!M54")} -> #REF! | K13: {=INDIRECT($B13&"!M75")} -> #REF! | L13: {=INDIRECT($B13&"!M69")+INDIRECT($B13&"!M70")} -> #REF! | M13: {=INDIRECT($B13&"!M77")-INDIRECT($B13&"!M75")-INDIRECT($B13&"!M69")-INDIRECT($B13&"!M70")} -> #REF! | N13: {=INDIRECT($B13&"!M115")} -> #REF! | O13: =SUM(G13:N13) -> #REF! | P13: {=INDIRECT($B13&"!M31")} -> #REF! | Q13: =P13/F13 -> #REF! | R13: {=INDIRECT($B13&"!M34")} -> #REF! | S13: =R13/F13 -> #REF! | T13: {=INDIRECT($B13&"!M38")} -> #REF! | V13: =T13/F13 -> #REF! | W13: {=INDIRECT($B13&"!M36")} -> #REF! | X13: =W13/F13 -> #REF! | Y13: =SUMIFS([1]客房!D:D,[1]客房!B:B,D13,[1]客房!C:C,"Reservation Fees 预订成本") -> #VALUE! | Z13: =SUMIFS([1]客房!D:D,[1]客房!B:B,D13,[1]客房!C:C," Total Cost of Sales 总销售成本") -> #VALUE! | AA13: {=INDIRECT($B13&"!M44")+INDIRECT($B13&"!M45")} -> #REF! | AB13: =SUMIFS([1]客房!D:D,[1]客房!B:B,D13,[1]客房!C:C,"Laundry 洗涤费") -> #VALUE! | AC13: {=INDIRECT($B13&"!M46")-Y13-Z13-AB13} -> #REF! | AD13: {=INDIRECT($B13&"!M47")-SUM(Y13:AC13)} -> #REF! | AF13: {=INDIRECT($B13&"!M60")} -> #REF! | AG13: {=INDIRECT($B13&"!M61")+INDIRECT($B13&"!M62")} -> #REF! | AH13: =SUMIFS([1]餐饮!D:D,[1]餐饮!B:B,D13,[1]餐饮!C:C,"Laundry 洗涤费") -> #VALUE! | AI13: {=INDIRECT($B13&"!M63")-AH13} -> #REF! | AJ13: {=INDIRECT($B13&"!M64")-SUM(AE13:AI13)} -> #REF! | AK13: =SUMIFS([1]新零售!D:D,[1]新零售!B:B,D13,[1]新零售!C:C,"Total Cost of Sales 总销售成本") -> #VALUE! | AL13: =SUMIFS([1]康乐温泉!C:C,[1]康乐温泉!A:A,D13,[1]康乐温泉!B:B,"Total Cost of Sales 总销售成本")+SUMIFS([1]康乐温泉!C:C,[1]康乐温泉!A:A,D13,[1]康乐温泉!B:B,"Total Other Expenses 其他费用合计") -> #VALUE! | AP13: {=INDIRECT($B13&"!M91")+INDIRECT($B13&"!M92")} -> #REF! | AQ13: {=INDIRECT($B13&"!M93")+INDIRECT($B13&"!M94")+INDIRECT($B13&"!M95")+INDIRECT($B13&"!M96")} -> #REF! | AR13: {=INDIRECT($B13&"!M98")+INDIRECT($B13&"!M99")} -> #REF! | AT13: {=INDIRECT($B13&"!M100")} -> #REF! | AU13: {=INDIRECT($B13&"!M103")+INDIRECT($B13&"!M104")} -> #REF! | AV13: {=INDIRECT($B13&"!M36")} -> #REF! | AW13: {=INDIRECT($B13&"!M105")-AV13} -> #REF! | AX13: =SUMIFS([1]能源!C:C,[1]能源!A:A,D13,[1]能源!B:B,"Electricity 电费") -> #VALUE! | AY13: =SUMIFS([1]能源!C:C,[1]能源!A:A,D13,[1]能源!B:B,"Steam 蒸汽费")+SUMIFS([1]能源!C:C,[1]能源!A:A,D13,[1]能源!B:B,"Geothermal water 地热水")+SUMIFS([1]能源!C:C,[1]能源!A:A,D13,[1]能源!B:B,"Water 水费") -> #VALUE! | AZ13: =SUMIFS([1]能源!C:C,[1]能源!A:A,D13,[1]能源!B:B,"Gas 煤气费")+SUMIFS([1]能源!C:C,[1]能源!A:A,D13,[1]能源!B:B,"Oil 燃油费") -> #VALUE! | BA13: =SUMIFS([1]能源!C:C,[1]能源!A:A,D13,[1]能源!B:B,"Heating 暖气") -> #VALUE! | BB13: =SUM(AX13:BA13) -> #VALUE! | BC13: =BB13/F13 -> #VALUE! | BD13: {=INDIRECT($B13&"!M101")-SUM(AX13:BA13)} -> #REF! | BG13: {=INDIRECT($B13&"!M119")} -> #REF! | BI13: {=INDIRECT($B13&"!M116")} -> #REF! | BK13: {=INDIRECT($B13&"!M123")} -> #REF! | BM13: {=INDIRECT($B13&"!M117")} -> #REF! | BN13: {=INDIRECT($B13&"!M118")+INDIRECT($B13&"!M120")} -> #REF! | BP13: {=-INDIRECT($B13&"!M114")+INDIRECT($B13&"!M115")-BG13-BI13-BM13-BN13} -> #REF!
A14: 增城逸林酒店 | B14: 逸林 | C14: 增城逸林酒店 | D14: 广州市荔碧凤悦酒店有限公司 | E14: =SUM(G14:M14)-F14 -> #REF! | F14: {=INDIRECT($B14&"!M16")} -> #REF! | G14: {=INDIRECT($B14&"!M43")} -> #REF! | H14: {=INDIRECT($B14&"!M52")+INDIRECT($B14&"!M53")} -> #REF! | I14: {=INDIRECT($B14&"!M55")} -> #REF! | J14: {=INDIRECT($B14&"!M54")} -> #REF! | K14: {=INDIRECT($B14&"!M75")} -> #REF! | L14: {=INDIRECT($B14&"!M69")+INDIRECT($B14&"!M70")} -> #REF! | M14: {=INDIRECT($B14&"!M77")-INDIRECT($B14&"!M75")-INDIRECT($B14&"!M69")-INDIRECT($B14&"!M70")} -> #REF! | N14: {=INDIRECT($B14&"!M115")} -> #REF! | O14: =SUM(G14:N14) -> #REF! | P14: {=INDIRECT($B14&"!M31")} -> #REF! | Q14: =P14/F14 -> #REF! | R14: {=INDIRECT($B14&"!M34")} -> #REF! | S14: =R14/F14 -> #REF! | T14: {=INDIRECT($B14&"!M38")} -> #REF! | V14: =T14/F14 -> #REF! | W14: {=INDIRECT($B14&"!M36")} -> #REF! | X14: =W14/F14 -> #REF! | Y14: =SUMIFS([1]客房!D:D,[1]客房!B:B,D14,[1]客房!C:C,"Reservation Fees 预订成本") -> #VALUE! | Z14: =SUMIFS([1]客房!D:D,[1]客房!B:B,D14,[1]客房!C:C," Total Cost of Sales 总销售成本") -> #VALUE! | AA14: {=INDIRECT($B14&"!M44")+INDIRECT($B14&"!M45")} -> #REF! | AB14: =SUMIFS([1]客房!D:D,[1]客房!B:B,D14,[1]客房!C:C,"Laundry 洗涤费") -> #VALUE! | AC14: {=INDIRECT($B14&"!M46")-Y14-Z14-AB14} -> #REF! | AD14: {=INDIRECT($B14&"!M47")-SUM(Y14:AC14)} -> #REF! | AF14: {=INDIRECT($B14&"!M60")} -> #REF! | AG14: {=INDIRECT($B14&"!M61")+INDIRECT($B14&"!M62")} -> #REF! | AH14: =SUMIFS([1]餐饮!D:D,[1]餐饮!B:B,D14,[1]餐饮!C:C,"Laundry 洗涤费") -> #VALUE! | AI14: {=INDIRECT($B14&"!M63")-AH14} -> #REF! | AJ14: {=INDIRECT($B14&"!M64")-SUM(AE14:AI14)} -> #REF! | AK14: =SUMIFS([1]新零售!D:D,[1]新零售!B:B,D14,[1]新零售!C:C,"Total Cost of Sales 总销售成本") -> #VALUE! | AL14: =SUMIFS([1]康乐温泉!C:C,[1]康乐温泉!A:A,D14,[1]康乐温泉!B:B,"Total Cost of Sales 总销售成本")+SUMIFS([1]康乐温泉!C:C,[1]康乐温泉!A:A,D14,[1]康乐温泉!B:B,"Total Other Expenses 其他费用合计") -> #VALUE! | AP14: {=INDIRECT($B14&"!M91")+INDIRECT($B14&"!M92")} -> #REF! | AQ14: {=INDIRECT($B14&"!M93")+INDIRECT($B14&"!M94")+INDIRECT($B14&"!M95")+INDIRECT($B14&"!M96")} -> #REF! | AR14: {=INDIRECT($B14&"!M98")+INDIRECT($B14&"!M99")} -> #REF! | AT14: {=INDIRECT($B14&"!M100")} -> #REF! | AU14: {=INDIRECT($B14&"!M103")+INDIRECT($B14&"!M104")} -> #REF! | AV14: {=INDIRECT($B14&"!M36")} -> #REF! | AW14: {=INDIRECT($B14&"!M105")-AV14} -> #REF! | AX14: =SUMIFS([1]能源!C:C,[1]能源!A:A,D14,[1]能源!B:B,"Electricity 电费") -> #VALUE! | AY14: =SUMIFS([1]能源!C:C,[1]能源!A:A,D14,[1]能源!B:B,"Steam 蒸汽费")+SUMIFS([1]能源!C:C,[1]能源!A:A,D14,[1]能源!B:B,"Geothermal water 地热水")+SUMIFS([1]能源!C:C,[1]能源!A:A,D14,[1]能源!B:B,"Water 水费") -> #VALUE! | AZ14: =SUMIFS([1]能源!C:C,[1]能源!A:A,D14,[1]能源!B:B,"Gas 煤气费")+SUMIFS([1]能源!C:C,[1]能源!A:A,D14,[1]能源!B:B,"Oil 燃油费") -> #VALUE! | BA14: =SUMIFS([1]能源!C:C,[1]能源!A:A,D14,[1]能源!B:B,"Heating 暖气") -> #VALUE! | BB14: =SUM(AX14:BA14) -> #VALUE! | BC14: =BB14/F14 -> #VALUE! | BD14: {=INDIRECT($B14&"!M101")-SUM(AX14:BA14)} -> #REF! | BG14: {=INDIRECT($B14&"!M119")} -> #REF! | BI14: {=INDIRECT($B14&"!M116")} -> #REF! | BK14: {=INDIRECT($B14&"!M123")} -> #REF! | BM14: {=INDIRECT($B14&"!M117")} -> #REF! | BN14: {=INDIRECT($B14&"!M118")+INDIRECT($B14&"!M120")} -> #REF! | BP14: {=-INDIRECT($B14&"!M114")+INDIRECT($B14&"!M115")-BG14-BI14-BM14-BN14} -> #REF!
A15: 云浮酒店 | B15: 云浮 | C15: 云浮酒店 | D15: 云浮市碧桂园凤凰酒店有限公司 | E15: =SUM(G15:M15)-F15 -> #REF! | F15: {=INDIRECT($B15&"!M16")} -> #REF! | G15: {=INDIRECT($B15&"!M43")} -> #REF! | H15: {=INDIRECT($B15&"!M52")+INDIRECT($B15&"!M53")} -> #REF! | I15: {=INDIRECT($B15&"!M55")} -> #REF! | J15: {=INDIRECT($B15&"!M54")} -> #REF! | K15: {=INDIRECT($B15&"!M75")} -> #REF! | L15: {=INDIRECT($B15&"!M69")+INDIRECT($B15&"!M70")} -> #REF! | M15: {=INDIRECT($B15&"!M77")-INDIRECT($B15&"!M75")-INDIRECT($B15&"!M69")-INDIRECT($B15&"!M70")} -> #REF! | N15: {=INDIRECT($B15&"!M115")} -> #REF! | O15: =SUM(G15:N15) -> #REF! | P15: {=INDIRECT($B15&"!M31")} -> #REF! | Q15: =P15/F15 -> #REF! | R15: {=INDIRECT($B15&"!M34")} -> #REF! | S15: =R15/F15 -> #REF! | T15: {=INDIRECT($B15&"!M38")} -> #REF! | V15: =T15/F15 -> #REF! | W15: {=INDIRECT($B15&"!M36")} -> #REF! | X15: =W15/F15 -> #REF! | Y15: =SUMIFS([1]客房!D:D,[1]客房!B:B,D15,[1]客房!C:C,"Reservation Fees 预订成本") -> #VALUE! | Z15: =SUMIFS([1]客房!D:D,[1]客房!B:B,D15,[1]客房!C:C," Total Cost of Sales 总销售成本") -> #VALUE! | AA15: {=INDIRECT($B15&"!M44")+INDIRECT($B15&"!M45")} -> #REF! | AB15: =SUMIFS([1]客房!D:D,[1]客房!B:B,D15,[1]客房!C:C,"Laundry 洗涤费") -> #VALUE! | AC15: {=INDIRECT($B15&"!M46")-Y15-Z15-AB15} -> #REF! | AD15: {=INDIRECT($B15&"!M47")-SUM(Y15:AC15)} -> #REF! | AF15: {=INDIRECT($B15&"!M60")} -> #REF! | AG15: {=INDIRECT($B15&"!M61")+INDIRECT($B15&"!M62")} -> #REF! | AH15: =SUMIFS([1]餐饮!D:D,[1]餐饮!B:B,D15,[1]餐饮!C:C,"Laundry 洗涤费") -> #VALUE! | AI15: {=INDIRECT($B15&"!M63")-AH15} -> #REF! | AJ15: {=INDIRECT($B15&"!M64")-SUM(AE15:AI15)} -> #REF! | AK15: =SUMIFS([1]新零售!D:D,[1]新零售!B:B,D15,[1]新零售!C:C,"Total Cost of Sales 总销售成本") -> #VALUE! | AL15: =SUMIFS([1]康乐温泉!C:C,[1]康乐温泉!A:A,D15,[1]康乐温泉!B:B,"Total Cost of Sales 总销售成本")+SUMIFS([1]康乐温泉!C:C,[1]康乐温泉!A:A,D15,[1]康乐温泉!B:B,"Total Other Expenses 其他费用合计") -> #VALUE! | AP15: {=INDIRECT($B15&"!M91")+INDIRECT($B15&"!M92")} -> #REF! | AQ15: {=INDIRECT($B15&"!M93")+INDIRECT($B15&"!M94")+INDIRECT($B15&"!M95")+INDIRECT($B15&"!M96")} -> #REF! | AR15: {=INDIRECT($B15&"!M98")+INDIRECT($B15&"!M99")} -> #REF! | AT15: {=INDIRECT($B15&"!M100")} -> #REF! | AU15: {=INDIRECT($B15&"!M103")+INDIRECT($B15&"!M104")} -> #REF! | AV15: {=INDIRECT($B15&"!M36")} -> #REF! | AW15: {=INDIRECT($B15&"!M105")-AV15} -> #REF! | AX15: =SUMIFS([1]能源!C:C,[1]能源!A:A,D15,[1]能源!B:B,"Electricity 电费") -> #VALUE! | AY15: =SUMIFS([1]能源!C:C,[1]能源!A:A,D15,[1]能源!B:B,"Steam 蒸汽费")+SUMIFS([1]能源!C:C,[1]能源!A:A,D15,[1]能源!B:B,"Geothermal water 地热水")+SUMIFS([1]能源!C:C,[1]能源!A:A,D15,[1]能源!B:B,"Water 水费") -> #VALUE! | AZ15: =SUMIFS([1]能源!C:C,[1]能源!A:A,D15,[1]能源!B:B,"Gas 煤气费")+SUMIFS([1]能源!C:C,[1]能源!A:A,D15,[1]能源!B:B,"Oil 燃油费") -> #VALUE! | BA15: =SUMIFS([1]能源!C:C,[1]能源!A:A,D15,[1]能源!B:B,"Heating 暖气") -> #VALUE! | BB15: =SUM(AX15:BA15) -> #VALUE! | BC15: =BB15/F15 -> #VALUE! | BD15: {=INDIRECT($B15&"!M101")-SUM(AX15:BA15)} -> #REF! | BG15: {=INDIRECT($B15&"!M119")} -> #REF! | BI15: {=INDIRECT($B15&"!M116")} -> #REF! | BK15: {=INDIRECT($B15&"!M123")} -> #REF! | BM15: {=INDIRECT($B15&"!M117")} -> #REF! | BN15: {=INDIRECT($B15&"!M118")+INDIRECT($B15&"!M120")} -> #REF! | BP15: {=-INDIRECT($B15&"!M114")+INDIRECT($B15&"!M115")-BG15-BI15-BM15-BN15} -> #REF!
A16: 金叶子酒店 | B16: 金叶子 | C16: 金叶子酒店 | D16: 广州金叶子酒店有限公司 | E16: =SUM(G16:M16)-F16 -> #REF! | F16: {=INDIRECT($B16&"!M16")} -> #REF! | G16: {=INDIRECT($B16&"!M43")} -> #REF! | H16: {=INDIRECT($B16&"!M52")+INDIRECT($B16&"!M53")} -> #REF! | I16: {=INDIRECT($B16&"!M55")} -> #REF! | J16: {=INDIRECT($B16&"!M54")} -> #REF! | K16: {=INDIRECT($B16&"!M75")} -> #REF! | L16: {=INDIRECT($B16&"!M69")+INDIRECT($B16&"!M70")} -> #REF! | M16: {=INDIRECT($B16&"!M77")-INDIRECT($B16&"!M75")-INDIRECT($B16&"!M69")-INDIRECT($B16&"!M70")} -> #REF! | N16: {=INDIRECT($B16&"!M115")} -> #REF! | O16: =SUM(G16:N16) -> #REF! | P16: {=INDIRECT($B16&"!M31")} -> #REF! | Q16: =P16/F16 -> #REF! | R16: {=INDIRECT($B16&"!M34")} -> #REF! | S16: =R16/F16 -> #REF! | T16: {=INDIRECT($B16&"!M38")} -> #REF! | V16: =T16/F16 -> #REF! | W16: {=INDIRECT($B16&"!M36")} -> #REF! | X16: =W16/F16 -> #REF! | Y16: =SUMIFS([1]客房!D:D,[1]客房!B:B,D16,[1]客房!C:C,"Reservation Fees 预订成本") -> #VALUE! | Z16: =SUMIFS([1]客房!D:D,[1]客房!B:B,D16,[1]客房!C:C," Total Cost of Sales 总销售成本") -> #VALUE! | AA16: {=INDIRECT($B16&"!M44")+INDIRECT($B16&"!M45")} -> #REF! | AB16: =SUMIFS([1]客房!D:D,[1]客房!B:B,D16,[1]客房!C:C,"Laundry 洗涤费") -> #VALUE! | AC16: {=INDIRECT($B16&"!M46")-Y16-Z16-AB16} -> #REF! | AD16: {=INDIRECT($B16&"!M47")-SUM(Y16:AC16)} -> #REF! | AF16: {=INDIRECT($B16&"!M60")} -> #REF! | AG16: {=INDIRECT($B16&"!M61")+INDIRECT($B16&"!M62")} -> #REF! | AH16: =SUMIFS([1]餐饮!D:D,[1]餐饮!B:B,D16,[1]餐饮!C:C,"Laundry 洗涤费") -> #VALUE! | AI16: {=INDIRECT($B16&"!M63")-AH16} -> #REF! | AJ16: {=INDIRECT($B16&"!M64")-SUM(AE16:AI16)} -> #REF! | AK16: =SUMIFS([1]新零售!D:D,[1]新零售!B:B,D16,[1]新零售!C:C,"Total Cost of Sales 总销售成本") -> #VALUE! | AL16: =SUMIFS([1]康乐温泉!C:C,[1]康乐温泉!A:A,D16,[1]康乐温泉!B:B,"Total Cost of Sales 总销售成本")+SUMIFS([1]康乐温泉!C:C,[1]康乐温泉!A:A,D16,[1]康乐温泉!B:B,"Total Other Expenses 其他费用合计") -> #VALUE! | AP16: {=INDIRECT($B16&"!M91")+INDIRECT($B16&"!M92")} -> #REF! | AQ16: {=INDIRECT($B16&"!M93")+INDIRECT($B16&"!M94")+INDIRECT($B16&"!M95")+INDIRECT($B16&"!M96")} -> #REF! | AR16: {=INDIRECT($B16&"!M98")+INDIRECT($B16&"!M99")} -> #REF! | AT16: {=INDIRECT($B16&"!M100")} -> #REF! | AU16: {=INDIRECT($B16&"!M103")+INDIRECT($B16&"!M104")} -> #REF! | AV16: {=INDIRECT($B16&"!M36")} -> #REF! | AW16: {=INDIRECT($B16&"!M105")-AV16} -> #REF! | AX16: =SUMIFS([1]能源!C:C,[1]能源!A:A,D16,[1]能源!B:B,"Electricity 电费") -> #VALUE! | AY16: =SUMIFS([1]能源!C:C,[1]能源!A:A,D16,[1]能源!B:B,"Steam 蒸汽费")+SUMIFS([1]能源!C:C,[1]能源!A:A,D16,[1]能源!B:B,"Geothermal water 地热水")+SUMIFS([1]能源!C:C,[1]能源!A:A,D16,[1]能源!B:B,"Water 水费") -> #VALUE! | AZ16: =SUMIFS([1]能源!C:C,[1]能源!A:A,D16,[1]能源!B:B,"Gas 煤气费")+SUMIFS([1]能源!C:C,[1]能源!A:A,D16,[1]能源!B:B,"Oil 燃油费") -> #VALUE! | BA16: =SUMIFS([1]能源!C:C,[1]能源!A:A,D16,[1]能源!B:B,"Heating 暖气") -> #VALUE! | BB16: =SUM(AX16:BA16) -> #VALUE! | BC16: =BB16/F16 -> #VALUE! | BD16: {=INDIRECT($B16&"!M101")-SUM(AX16:BA16)} -> #REF! | BG16: {=INDIRECT($B16&"!M119")} -> #REF! | BI16: {=INDIRECT($B16&"!M116")} -> #REF! | BK16: {=INDIRECT($B16&"!M123")} -> #REF! | BM16: {=INDIRECT($B16&"!M117")} -> #REF! | BN16: {=INDIRECT($B16&"!M118")+INDIRECT($B16&"!M120")} -> #REF! | BP16: {=-INDIRECT($B16&"!M114")+INDIRECT($B16&"!M115")-BG16-BI16-BM16-BN16} -> #REF!
